<mujoco model="g1">
    <compiler angle="radian" meshdir="./meshes/g1"/>

    <default>
        <default class="g1">
            <geom contype="0" conaffinity="0"/>

            <joint frictionloss="0.1" solimplimit="0.97 0.995 0.001"/>

            <default class="hip">
                <default class="hip_pitch">
                    <joint axis="0 1 0" range="-2.5307 2.8798" actuatorfrcrange="-88 88" armature="0.01017752004"/>
                </default>
                <default class="hip_roll">
                    <joint axis="1 0 0" actuatorfrcrange="-139 139" armature="0.025101925"/>
                </default>
                <default class="hip_yaw">
                    <joint axis="0 0 1" range="-2.7576 2.7576" actuatorfrcrange="-88 88" armature="0.01017752004"/>
                </default>
            </default>
            <default class="knee">
                <joint axis="0 1 0" range="-0.087267 2.8798" actuatorfrcrange="-139 139" armature="0.025101925"/>
            </default>
            <default class="ankle">
                <default class="ankle_pitch">
                    <joint axis="0 1 0" range="-0.87267 0.5236" actuatorfrcrange="-50 50" armature="0.00721945"/>
                </default>
                <default class="ankle_roll">
                    <joint axis="1 0 0" range="-0.2618 0.2618" actuatorfrcrange="-50 50" armature="0.00721945"/>
                </default>
            </default>
            <default class="waist_yaw">
                <joint axis="0 0 1" range="-2.618 2.618" actuatorfrcrange="-88 88" armature="0.01017752004"/>
            </default>
            <default class="waist_pitch">
                <joint axis="0 1 0" range="-0.52 0.52" actuatorfrcrange="-50 50" armature="0.00721945"/>
            </default>
            <default class="waist_roll">
                <joint axis="1 0 0" range="-0.52 0.52" actuatorfrcrange="-50 50" armature="0.00721945"/>
            </default>
            <default class="shoulder">
                <default class="shoulder_pitch">
                    <joint axis="0 1 0" range="-3.0892 2.6704" actuatorfrcrange="-25 25" armature="0.003609725"/>
                </default>
                <default class="shoulder_roll">
                    <joint axis="1 0 0" actuatorfrcrange="-25 25" armature="0.003609725"/>
                </default>
                <default class="shoulder_yaw">
                    <joint axis="0 0 1" range="-2.618 2.618" actuatorfrcrange="-25 25" armature="0.003609725"/>
                </default>
            </default>
            <default class="elbow">
                <joint axis="0 1 0" range="-1.0472 2.0944" actuatorfrcrange="-25 25" armature="0.003609725"/>
            </default>
            <default class="wrist">
                <default class="wrist_roll">
                    <joint axis="1 0 0" range="-1.97222 1.97222" actuatorfrcrange="-25 25" armature="0.003609725"/>
                </default>
                <default class="wrist_pitch">
                    <joint axis="0 1 0" range="-1.61443 1.61443" actuatorfrcrange="-5 5" armature="0.00425"/>
                </default>
                <default class="wrist_yaw">
                    <joint axis="0 0 1" range="-1.61443 1.61443" actuatorfrcrange="-5 5" armature="0.00425"/>
                </default>
            </default>

            <default class="visual">
                <geom group="2" type="mesh" density="0" material="silver"/>
            </default>
            <default class="collision">
                <geom group="3" rgba=".2 .6 .2 .3" contype="1" conaffinity="1"/>
                <default class="foot">
                    <geom size="0.085 0.03 0.005"/>
                </default>
            </default>
            <site group="5" rgba="1 0 0 1"/>
        </default>
    </default>

    <asset>
        <material name="silver" rgba="0.7 0.7 0.7 1"/>
        <material name="black" rgba="0.2 0.2 0.2 1"/>

        <mesh name="pelvis" file="pelvis.STL"/>
        <mesh name="pelvis_contour_link" file="pelvis_contour_link.STL"/>
        <mesh name="left_hip_pitch_link" file="left_hip_pitch_link.STL"/>
        <mesh name="left_hip_roll_link" file="left_hip_roll_link.STL"/>
        <mesh name="left_hip_yaw_link" file="left_hip_yaw_link.STL"/>
        <mesh name="left_knee_link" file="left_knee_link.STL"/>
        <mesh name="left_ankle_pitch_link"
              file="left_ankle_pitch_link.STL"/>
        <mesh name="left_ankle_roll_link" file="left_ankle_roll_link.STL"/>
        <mesh name="right_hip_pitch_link" file="right_hip_pitch_link.STL"/>
        <mesh name="right_hip_roll_link" file="right_hip_roll_link.STL"/>
        <mesh name="right_hip_yaw_link" file="right_hip_yaw_link.STL"/>
        <mesh name="right_knee_link" file="right_knee_link.STL"/>
        <mesh name="right_ankle_pitch_link"
              file="right_ankle_pitch_link.STL"/>
        <mesh name="right_ankle_roll_link"
              file="right_ankle_roll_link.STL"/>
        <mesh name="waist_yaw_link" file="waist_yaw_link_rev_1_0.STL"/>
        <mesh name="waist_roll_link" file="waist_roll_link_rev_1_0.STL"/>
        <mesh name="torso_link" file="torso_link_rev_1_0.STL"/>
        <mesh name="logo_link" file="logo_link.STL"/>
        <mesh name="head_link" file="head_link.STL"/>
        <mesh name="left_shoulder_pitch_link"
              file="left_shoulder_pitch_link.STL"/>
        <mesh name="left_shoulder_roll_link"
              file="left_shoulder_roll_link.STL"/>
        <mesh name="left_shoulder_yaw_link"
              file="left_shoulder_yaw_link.STL"/>
        <mesh name="left_elbow_link" file="left_elbow_link.STL"/>
        <mesh name="left_wrist_roll_link" file="left_wrist_roll_link.STL"/>
        <mesh name="left_wrist_pitch_link"
              file="left_wrist_pitch_link.STL"/>
        <mesh name="left_wrist_yaw_link" file="left_wrist_yaw_link.STL"/>
        <mesh name="right_shoulder_pitch_link"
              file="right_shoulder_pitch_link.STL"/>
        <mesh name="right_shoulder_roll_link"
              file="right_shoulder_roll_link.STL"/>
        <mesh name="right_shoulder_yaw_link"
              file="right_shoulder_yaw_link.STL"/>
        <mesh name="right_elbow_link" file="right_elbow_link.STL"/>
        <mesh name="right_wrist_roll_link"
              file="right_wrist_roll_link.STL"/>
        <mesh name="right_wrist_pitch_link"
              file="right_wrist_pitch_link.STL"/>
        <mesh name="right_wrist_yaw_link" file="right_wrist_yaw_link.STL"/>
        <mesh name="half_sphere" file="half_sphere.obj"/>
    </asset>

    <worldbody>
        <body name="pelvis" pos="0 0 0.793" childclass="g1">
            <inertial pos="0 0 -0.07605" quat="1 0 -0.000399148 0" mass="3.813" diaginertia="0.010549 0.0093089 0.0079184"/>
            <freejoint name="floating_base_joint"/>
            <geom class="visual" material="black" mesh="pelvis"/>
            <geom class="visual" mesh="pelvis_contour_link"/>
            <geom mesh="pelvis_contour_link" class="visual"/>
            <geom name="pelvis_collision" class="collision" type="sphere" size="0.07" pos="0 0 -0.08"/>
            <site name="imu_in_pelvis" size="0.01" pos="0.04525 0 -0.08339"/>
            <site name="pelvis" size="0.01" pos="0 0 0"/>
            <body name="left_hip_pitch_link" pos="0 0.064452 -0.1027">
                <inertial pos="0.002741 0.047791 -0.02606" quat="0.954862 0.293964 0.0302556 0.030122" mass="1.35"
                          diaginertia="0.00181517 0.00153422 0.00116212"/>
                <joint name="left_hip_pitch_joint" class="hip_pitch"/>
                <geom class="visual" material="black" mesh="left_hip_pitch_link"/>
                <geom material="black" mesh="left_hip_pitch_link" class="visual"/>
                <body name="left_hip_roll_link" pos="0 0.052 -0.030465" quat="0.996179 0 -0.0873386 0">
                    <inertial pos="0.029812 -0.001045 -0.087934" quat="0.977808 -1.97119e-05 0.205576 -0.0403793" mass="1.52"
                              diaginertia="0.00254986 0.00241169 0.00148755"/>
                    <joint name="left_hip_roll_joint" class="hip_roll" range="-0.5236 2.9671"/>
                    <geom class="visual" mesh="left_hip_roll_link"/>
                    <geom mesh="left_hip_roll_link" class="visual"/>
                    <geom name="left_thigh" class="collision" type="capsule" size="0.05" fromto="0.02 0 0 0.02 0 -0.2"/>
                    <body name="left_hip_yaw_link" pos="0.025001 0 -0.12412">
                        <inertial pos="-0.057709 -0.010981 -0.15078" quat="0.600598 0.15832 0.223482 0.751181" mass="1.702"
                                  diaginertia="0.00776166 0.00717575 0.00160139"/>
                        <joint name="left_hip_yaw_joint" class="hip_yaw"/>
                        <geom class="visual" mesh="left_hip_yaw_link"/>
                        <body name="left_knee_link" pos="-0.078273 0.0021489 -0.17734" quat="0.996179 0 0.0873386 0">
                            <inertial pos="0.005457 0.003964 -0.12074" quat="0.923418 -0.0327699 0.0158246 0.382067" mass="1.932"
                                      diaginertia="0.0113804 0.0112778 0.00146458"/>
                            <joint name="left_knee_joint" class="knee"/>
                            <geom class="visual" mesh="left_knee_link"/>
                            <geom name="left_shin" class="collision" type="capsule" size="0.04" fromto="0.02 0 0 0.02 0 -0.25"/>
                            <body name="left_ankle_pitch_link" pos="0 -9.4445e-05 -0.30001">
                                <inertial pos="-0.007269 0 0.011137" quat="0.603053 0.369225 0.369225 0.603053" mass="0.074"
                                          diaginertia="1.89e-05 1.40805e-05 6.9195e-06"/>
                                <joint name="left_ankle_pitch_joint" class="ankle_pitch"/>
                                <geom class="visual" mesh="left_ankle_pitch_link"/>
                                <body name="left_ankle_roll_link" pos="0 0 -0.017558">
                                    <site name="left_foot" rgba="1 0 0 1"/>
                                    <inertial pos="0.026505 0 -0.016425" quat="-0.000481092 0.728482 -0.000618967 0.685065" mass="0.608"
                                              diaginertia="0.00167218 0.0016161 0.000217621"/>
                                    <joint name="left_ankle_roll_joint" class="ankle_roll"/>
                                    <geom class="visual" material="black" mesh="left_ankle_roll_link"/>
                                    <geom name="left_foot1_collision" type="capsule" size="0.01" class="collision" fromto="0.1 -0.026 -0.025 0.05 -0.027 -0.025"/>
                                    <geom name="left_foot2_collision" type="capsule" size="0.01" class="collision" fromto="-0.044 -0.018 -0.025 0.123 -0.018 -0.025"/>
                                    <geom name="left_foot3_collision" type="capsule" size="0.01" class="collision" fromto="-0.052 -0.01 -0.025 0.13 -0.01 -0.025"/>
                                    <geom name="left_foot4_collision" type="capsule" size="0.01" class="collision" fromto="-0.054 0 -0.025 0.132 0 -0.025"/>
                                    <geom name="left_foot5_collision" type="capsule" size="0.01" class="collision" fromto="-0.052 0.01 -0.025 0.13 0.01 -0.025"/>
                                    <geom name="left_foot6_collision" type="capsule" size="0.01" class="collision" fromto="-0.044 0.018 -0.025 0.123 0.018 -0.025"/>
                                    <geom name="left_foot7_collision" type="capsule" size="0.01" class="collision" fromto="0.1 0.026 -0.025 0.05 0.026 -0.025"/>
                                </body>
                            </body>
                        </body>
                    </body>
                </body>
            </body>
            <body name="right_hip_pitch_link" pos="0 -0.064452 -0.1027">
                <inertial pos="0.002741 -0.047791 -0.02606" quat="0.954862 -0.293964 0.0302556 -0.030122" mass="1.35"
                          diaginertia="0.00181517 0.00153422 0.00116212"/>
                <joint name="right_hip_pitch_joint" class="hip_pitch"/>
                <geom class="visual" material="black" mesh="right_hip_pitch_link"/>
                <body name="right_hip_roll_link" pos="0 -0.052 -0.030465" quat="0.996179 0 -0.0873386 0">
                    <inertial pos="0.029812 0.001045 -0.087934" quat="0.977808 1.97119e-05 0.205576 0.0403793" mass="1.52"
                              diaginertia="0.00254986 0.00241169 0.00148755"/>
                    <joint name="right_hip_roll_joint" class="hip_roll" range="-2.9671 0.5236"/>
                    <geom class="visual" mesh="right_hip_roll_link"/>
                    <geom name="right_thigh" class="collision" type="capsule" size="0.05" fromto="0.02 0 0 0.02 0 -0.2"/>
                    <body name="right_hip_yaw_link" pos="0.025001 0 -0.12412">
                        <inertial pos="-0.057709 0.010981 -0.15078" quat="0.751181 0.223482 0.15832 0.600598" mass="1.702"
                                  diaginertia="0.00776166 0.00717575 0.00160139"/>
                        <joint name="right_hip_yaw_joint" class="hip_yaw"/>
                        <geom class="visual" mesh="right_hip_yaw_link"/>
                        <body name="right_knee_link" pos="-0.078273 -0.0021489 -0.17734" quat="0.996179 0 0.0873386 0">
                            <inertial pos="0.005457 -0.003964 -0.12074" quat="0.923439 0.0345276 0.0116333 -0.382012" mass="1.932"
                                      diaginertia="0.011374 0.0112843 0.00146452"/>
                            <joint name="right_knee_joint" class="knee"/>
                            <geom class="visual" mesh="right_knee_link"/>
                            <geom name="right_shin" class="collision" type="capsule" size="0.04" fromto="0.02 0 0 0.02 0 -0.25"/>
                            <body name="right_ankle_pitch_link" pos="0 9.4445e-05 -0.30001">
                                <inertial pos="-0.007269 0 0.011137" quat="0.603053 0.369225 0.369225 0.603053" mass="0.074"
                                          diaginertia="1.89e-05 1.40805e-05 6.9195e-06"/>
                                <joint name="right_ankle_pitch_joint" class="ankle_pitch"/>
                                <geom class="visual" mesh="right_ankle_pitch_link"/>
                                <body name="right_ankle_roll_link" pos="0 0 -0.017558">
                                    <site name="right_foot" pos="0 0 0"/>
                                    <inertial pos="0.026505 0 -0.016425" quat="0.000481092 0.728482 0.000618967 0.685065" mass="0.608"
                                              diaginertia="0.00167218 0.0016161 0.000217621"/>
                                    <joint name="right_ankle_roll_joint" class="ankle_roll"/>
                                    <geom class="visual" material="black" mesh="right_ankle_roll_link"/>
                                    <geom name="right_foot1_collision" type="capsule" size="0.01" class="collision" fromto="0.1 -0.026 -0.025 0.05 -0.026 -0.025"/>
                                    <geom name="right_foot2_collision" type="capsule" size="0.008" class="collision" fromto="-0.044 -0.018 -0.025 0.123 -0.018 -0.025"/>
                                    <geom name="right_foot3_collision" type="capsule" size="0.01" class="collision" fromto="-0.052 -0.01 -0.025 0.13 -0.01 -0.025"/>
                                    <geom name="right_foot4_collision" type="capsule" size="0.01" class="collision" fromto="-0.054 0 -0.025 0.132 0 -0.025"/>
                                    <geom name="right_foot5_collision" type="capsule" size="0.01" class="collision" fromto="-0.052 0.01 -0.025 0.13 0.01 -0.025"/>
                                    <geom name="right_foot6_collision" type="capsule" size="0.008" class="collision" fromto="-0.044 0.018 -0.025 0.123 0.018 -0.025"/>
                                    <geom name="right_foot7_collision" type="capsule" size="0.01" class="collision" fromto="0.1 0.026 -0.025 0.05 0.026 -0.025"/>
                                </body>
                            </body>
                        </body>
                    </body>
                </body>
            </body>
            <body name="waist_yaw_link">
                <inertial pos="0.003494 0.000233 0.018034" quat="0.289697 0.591001 -0.337795 0.672821" mass="0.214"
                          diaginertia="0.000163531 0.000107714 0.000102205"/>
                <joint name="waist_yaw_joint" class="waist_yaw"/>
                <geom class="visual" mesh="waist_yaw_link"/>
                <body name="waist_roll_link" pos="-0.0039635 0 0.044">
                    <inertial pos="0 2.3e-05 0" quat="0.5 0.5 -0.5 0.5" mass="0.086" diaginertia="8.245e-06 7.079e-06 6.339e-06"/>
                    <joint name="waist_roll_joint" class="waist_roll"/>
                    <geom class="visual" mesh="waist_roll_link"/>
                    <body name="torso_link">
                        <inertial pos="0.00203158 0.000339683 0.184568" quat="0.999803 -6.03319e-05 0.0198256 0.00131986"
                                  mass="7.818" diaginertia="0.121847 0.109825 0.0273735"/>
                        <joint name="waist_pitch_joint" class="waist_pitch"/>
                        <geom class="visual" mesh="torso_link"/>
                        <geom pos="0.0039635 0 -0.044" quat="1 0 0 0" class="visual" material="black" mesh="logo_link"/>
                        <geom pos="0.0039635 0 -0.044" class="visual" material="black" mesh="head_link"/>

                        <geom name="torso_collision1" class="collision" type="capsule" size="0.073" fromto="0.005 -0.032 .22 0.005 0.032 .22"/>
                        <geom name="torso_collision2" class="collision" type="capsule" size="0.07" fromto="0.005 -0.028 .13 0.005 0.028 .13"/>
                        <geom name="torso_collision3" class="collision" type="capsule" size="0.065" fromto="0.005 -0.02 .06 0.005 0.02 .06"/>
                        <geom name="head_collision" class="collision" type="capsule" size="0.068" fromto="0.01 0 .41 0.01 0 .42"/>

                        <site name="imu_in_torso" size="0.01" pos="-0.03959 -0.00224 0.14792"/>
                        <site name="mid360" size="0.01" pos="0.0002835 0.00003 0.41618" quat="0.00000094 -0.99979404 0.00004632 0.02029493"/>
                        <body name="left_shoulder_pitch_link" pos="0.0039563 0.10022 0.24778"
                              quat="0.990264 0.139201 1.38722e-05 -9.86868e-05">
                            <inertial pos="0 0.035892 -0.011628" quat="0.654152 0.0130458 -0.326267 0.68225" mass="0.718"
                                      diaginertia="0.000465864 0.000432842 0.000406394"/>
                            <joint name="left_shoulder_pitch_joint" class="shoulder_pitch"/>
                            <geom class="visual" mesh="left_shoulder_pitch_link"/>
                            <geom size="0.03 0.025" pos="0 0.04 -0.01" quat="0.707107 0 0.707107 0" type="cylinder" class="visual"/>
                            <body name="left_shoulder_roll_link" pos="0 0.038 -0.013831" quat="0.990268 -0.139172 0 0">
                                <inertial pos="-0.000227 0.00727 -0.063243" quat="0.701256 -0.0196223 -0.00710317 0.712604" mass="0.643"
                                          diaginertia="0.000691311 0.000618011 0.000388977"/>
                                <joint name="left_shoulder_roll_joint" range="-1.5882 2.2515" class="shoulder_roll"/>
                                <geom class="visual" mesh="left_shoulder_roll_link"/>
                                <geom size="0.03 0.015" pos="-0.004 0.006 -0.053" type="cylinder" class="visual"/>
                                <body name="left_shoulder_yaw_link" pos="0 0.00624 -0.1032">
                                    <inertial pos="0.010773 -0.002949 -0.072009" quat="0.716879 -0.0964829 -0.0679942 0.687134"
                                              mass="0.734" diaginertia="0.00106187 0.00103217 0.000400661"/>
                                    <joint name="left_shoulder_yaw_joint" class="shoulder_yaw"/>
                                    <geom class="visual" mesh="left_shoulder_yaw_link"/>
                                    <geom name="left_shoulder_yaw_collision" class="collision" type="capsule" size="0.035" fromto="0 0 -0.08 0 0 0.05"/>
                                    <body name="left_elbow_link" pos="0.015783 0 -0.080518">
                                        <inertial pos="0.064956 0.004454 -0.010062" quat="0.541765 0.636132 0.388821 0.388129" mass="0.6"
                                                  diaginertia="0.000443035 0.000421612 0.000259353"/>
                                        <joint name="left_elbow_joint" class="elbow"/>
                                        <geom class="visual" mesh="left_elbow_link"/>
                                        <geom name="left_elbow_yaw_collision" class="collision" type="capsule" size="0.035" fromto="-0.01 0 -0.01 0.12 0 -0.01"/>
                                        <body name="left_wrist_roll_link" pos="0.1 0.00188791 -0.01">
                                            <inertial pos="0.0171394 0.000537591 4.8864e-07" quat="0.575338 0.411667 -0.574906 0.411094"
                                                      mass="0.085445" diaginertia="5.48211e-05 4.96646e-05 3.57798e-05"/>
                                            <joint name="left_wrist_roll_joint" class="wrist_roll"/>
                                            <geom class="visual" mesh="left_wrist_roll_link"/>
                                            <body name="left_wrist_pitch_link" pos="0.038 0 0">
                                                <inertial pos="0.0229999 -0.00111685 -0.00111658" quat="0.249998 0.661363 0.293036 0.643608"
                                                          mass="0.48405" diaginertia="0.000430353 0.000429873 0.000164648"/>
                                                <joint name="left_wrist_pitch_joint" class="wrist_pitch"/>
                                                <geom class="visual" mesh="left_wrist_pitch_link"/>
                                                <body name="left_wrist_yaw_link" pos="0.046 0 0">
                                                    <inertial pos="0.0708244 0.000191745 0.00161742" quat="0.510571 0.526295 0.468078 0.493188"
                                                              mass="0.254576" diaginertia="0.000646113 0.000559993 0.000147566"/>
                                                    <joint name="left_wrist_yaw_joint" class="wrist_yaw"/>
                                                    <geom class="visual" mesh="left_wrist_yaw_link"/>
                                                    <geom pos="0.029 0.003 0" quat="0.707106 0 0.707106 0" class="visual" mesh="half_sphere"/>
                                                    <site name="left_palm" pos="0.08 0 0" size="0.01"/>
                                                    <geom type="mesh" pos="0.029 0.003 0" quat="0.707106 0 0.707106 0" name="left_hand_collision" class="collision" mesh="half_sphere"/>
                                                </body>
                                            </body>
                                        </body>
                                    </body>
                                </body>
                            </body>
                        </body>
                        <body name="right_shoulder_pitch_link" pos="0.0039563 -0.10021 0.24778"
                              quat="0.990264 -0.139201 1.38722e-05 9.86868e-05">
                            <inertial pos="0 -0.035892 -0.011628" quat="0.68225 -0.326267 0.0130458 0.654152" mass="0.718"
                                      diaginertia="0.000465864 0.000432842 0.000406394"/>
                            <joint name="right_shoulder_pitch_joint" class="shoulder_pitch"/>
                            <geom class="visual" mesh="right_shoulder_pitch_link"/>
                            <geom size="0.03 0.025" pos="0 -0.04 -0.01" quat="0.707107 0 0.707107 0" type="cylinder" class="visual"/>
                            <body name="right_shoulder_roll_link" pos="0 -0.038 -0.013831" quat="0.990268 0.139172 0 0">
                                <inertial pos="-0.000227 -0.00727 -0.063243" quat="0.712604 -0.00710317 -0.0196223 0.701256"
                                          mass="0.643" diaginertia="0.000691311 0.000618011 0.000388977"/>
                                <joint name="right_shoulder_roll_joint" range="-2.2515 1.5882" class="shoulder_roll"/>
                                <geom class="visual" mesh="right_shoulder_roll_link"/>
                                <geom size="0.03 0.015" pos="-0.004 -0.006 -0.053" type="cylinder" class="visual"/>
                                <body name="right_shoulder_yaw_link" pos="0 -0.00624 -0.1032">
                                    <inertial pos="0.010773 0.002949 -0.072009" quat="0.687134 -0.0679942 -0.0964829 0.716879"
                                              mass="0.734" diaginertia="0.00106187 0.00103217 0.000400661"/>
                                    <joint name="right_shoulder_yaw_joint" class="shoulder_yaw"/>
                                    <geom class="visual" mesh="right_shoulder_yaw_link"/>
                                    <geom name="right_shoulder_yaw_collision" class="collision" type="capsule" size="0.035" fromto="0 0 -0.08 0 0 0.05"/>
                                    <body name="right_elbow_link" pos="0.015783 0 -0.080518">
                                        <inertial pos="0.064956 -0.004454 -0.010062" quat="0.388129 0.388821 0.636132 0.541765" mass="0.6"
                                                  diaginertia="0.000443035 0.000421612 0.000259353"/>
                                        <joint name="right_elbow_joint" class="elbow"/>
                                        <geom class="visual" mesh="right_elbow_link"/>
                                        <geom name="right_elbow_yaw_collision" class="collision" type="capsule" size="0.035" fromto="-0.01 0 -0.01 0.12 0 -0.01"/>
                                        <body name="right_wrist_roll_link" pos="0.1 -0.00188791 -0.01">
                                            <inertial pos="0.0171394 -0.000537591 4.8864e-07" quat="0.411667 0.575338 -0.411094 0.574906"
                                                      mass="0.085445" diaginertia="5.48211e-05 4.96646e-05 3.57798e-05"/>
                                            <joint name="right_wrist_roll_joint" class="wrist_roll"/>
                                            <geom class="visual" mesh="right_wrist_roll_link"/>
                                            <body name="right_wrist_pitch_link" pos="0.038 0 0">
                                                <inertial pos="0.0229999 0.00111685 -0.00111658" quat="0.643608 0.293036 0.661363 0.249998"
                                                          mass="0.48405" diaginertia="0.000430353 0.000429873 0.000164648"/>
                                                <joint name="right_wrist_pitch_joint" class="wrist_pitch"/>
                                                <geom class="visual" mesh="right_wrist_pitch_link"/>
                                                <body name="right_wrist_yaw_link" pos="0.046 0 0">
                                                    <inertial pos="0.0708244 -0.000191745 0.00161742" quat="0.493188 0.468078 0.526295 0.510571"
                                                              mass="0.254576" diaginertia="0.000646113 0.000559993 0.000147566"/>
                                                    <joint name="right_wrist_yaw_joint" class="wrist_yaw"/>
                                                    <geom class="visual" mesh="right_wrist_yaw_link"/>
                                                    <geom pos="0.029 -0.003 0" quat="0.707106 0 0.707106 0" class="visual" mesh="half_sphere"/>
                                                    <site name="right_palm" pos="0.08 0 0" size="0.01"/>
                                                    <geom type="mesh" pos="0.029 -0.003 0" quat="0.707106 0 0.707106 0" name="right_hand_collision" class="collision" mesh="half_sphere"/>
                                                </body>
                                            </body>
                                        </body>
                                    </body>
                                </body>
                            </body>
                        </body>
                    </body>
                </body>
            </body>
        </body>
        <body name="terrain_boxes">
            <geom name="terrain_box_2" type="box" size="0.5 0.75 0.19" pos="5.00 -30.00 0.19" euler="0 0 -0.57" rgba="0.2 0.5 0.9 1" contype="1" conaffinity="1" friction="1 0.005 0.0001" />
            <geom name="terrain_box_3" type="box" size="0.5 0.75 0.38" pos="5.00 -25.00 0.38" euler="0 0 -0.31" rgba="0.95 0.75 0.2 1" contype="1" conaffinity="1" friction="1 0.005 0.0001" />
            <geom name="terrain_box_4" type="box" size="0.5 0.75 0.29" pos="5.00 -20.00 0.29" euler="0 0 0.28" rgba="0.2 0.8 0.4 1" contype="1" conaffinity="1" friction="1 0.005 0.0001" />
            <geom name="terrain_box_5" type="box" size="0.5 0.75 0.19" pos="5.00 -15.00 0.19" euler="0 0 0.11" rgba="0.2 0.5 0.9 1" contype="1" conaffinity="1" friction="1 0.005 0.0001" />
            <geom name="terrain_box_6" type="box" size="0.5 0.75 0.19" pos="5.00 -10.00 0.19" euler="0 0 -0.56" rgba="0.2 0.5 0.9 1" contype="1" conaffinity="1" friction="1 0.005 0.0001" />
            <geom name="terrain_box_7" type="box" size="0.5 0.75 0.29" pos="5.00 -5.00 0.29" euler="0 0 -0.32" rgba="0.2 0.8 0.4 1" contype="1" conaffinity="1" friction="1 0.005 0.0001" />
            <geom name="terrain_box_8" type="box" size="0.5 0.75 0.19" pos="5.00 0.00 0.19" euler="0 0 0.07" rgba="0.2 0.5 0.9 1" contype="1" conaffinity="1" friction="1 0.005 0.0001" />
            <geom name="terrain_box_9" type="box" size="0.5 0.75 0.46" pos="5.00 5.00 0.46" euler="0 0 -0.34" rgba="0.9 0.3 0.3 1" contype="1" conaffinity="1" friction="1 0.005 0.0001" />
            <geom name="terrain_box_10" type="box" size="0.5 0.75 0.38" pos="5.00 10.00 0.38" euler="0 0 0.37" rgba="0.95 0.75 0.2 1" contype="1" conaffinity="1" friction="1 0.005 0.0001" />
            <geom name="terrain_box_11" type="box" size="0.5 0.75 0.19" pos="5.00 15.00 0.19" euler="0 0 0.31" rgba="0.2 0.5 0.9 1" contype="1" conaffinity="1" friction="1 0.005 0.0001" />
            <geom name="terrain_box_12" type="box" size="0.5 0.75 0.29" pos="5.00 20.00 0.29" euler="0 0 0.24" rgba="0.2 0.8 0.4 1" contype="1" conaffinity="1" friction="1 0.005 0.0001" />
            <geom name="terrain_box_13" type="box" size="0.5 0.75 0.38" pos="5.00 25.00 0.38" euler="0 0 -0.27" rgba="0.95 0.75 0.2 1" contype="1" conaffinity="1" friction="1 0.005 0.0001" />
            <geom name="terrain_box_14" type="box" size="0.5 0.75 0.29" pos="5.00 30.00 0.29" euler="0 0 0.55" rgba="0.2 0.8 0.4 1" contype="1" conaffinity="1" friction="1 0.005 0.0001" />
            <geom name="terrain_box_15" type="box" size="0.5 0.75 0.38" pos="10.00 -30.00 0.38" euler="0 0 -0.48" rgba="0.95 0.75 0.2 1" contype="1" conaffinity="1" friction="1 0.005 0.0001" />
            <geom name="terrain_box_16" type="box" size="0.5 0.75 0.46" pos="10.00 -25.00 0.46" euler="0 0 -0.48" rgba="0.9 0.3 0.3 1" contype="1" conaffinity="1" friction="1 0.005 0.0001" />
            <geom name="terrain_box_17" type="box" size="0.5 0.75 0.38" pos="10.00 -20.00 0.38" euler="0 0 0.12" rgba="0.95 0.75 0.2 1" contype="1" conaffinity="1" friction="1 0.005 0.0001" />
            <geom name="terrain_box_18" type="box" size="0.5 0.75 0.19" pos="10.00 -15.00 0.19" euler="0 0 0.28" rgba="0.2 0.5 0.9 1" contype="1" conaffinity="1" friction="1 0.005 0.0001" />
            <geom name="terrain_box_19" type="box" size="0.5 0.75 0.19" pos="10.00 -10.00 0.19" euler="0 0 0.57" rgba="0.2 0.5 0.9 1" contype="1" conaffinity="1" friction="1 0.005 0.0001" />
            <geom name="terrain_box_20" type="box" size="0.5 0.75 0.46" pos="10.00 -5.00 0.46" euler="0 0 -0.51" rgba="0.9 0.3 0.3 1" contype="1" conaffinity="1" friction="1 0.005 0.0001" />
            <geom name="terrain_box_21" type="box" size="0.5 0.75 0.38" pos="10.00 0.00 0.38" euler="0 0 0.40" rgba="0.95 0.75 0.2 1" contype="1" conaffinity="1" friction="1 0.005 0.0001" />
            <geom name="terrain_box_22" type="box" size="0.5 0.75 0.38" pos="10.00 5.00 0.38" euler="0 0 0.09" rgba="0.95 0.75 0.2 1" contype="1" conaffinity="1" friction="1 0.005 0.0001" />
            <geom name="terrain_box_23" type="box" size="0.5 0.75 0.19" pos="10.00 10.00 0.19" euler="0 0 -0.55" rgba="0.2 0.5 0.9 1" contype="1" conaffinity="1" friction="1 0.005 0.0001" />
            <geom name="terrain_box_24" type="box" size="0.5 0.75 0.29" pos="10.00 15.00 0.29" euler="0 0 0.33" rgba="0.2 0.8 0.4 1" contype="1" conaffinity="1" friction="1 0.005 0.0001" />
            <geom name="terrain_box_25" type="box" size="0.5 0.75 0.19" pos="10.00 20.00 0.19" euler="0 0 0.43" rgba="0.2 0.5 0.9 1" contype="1" conaffinity="1" friction="1 0.005 0.0001" />
            <geom name="terrain_box_26" type="box" size="0.5 0.75 0.19" pos="10.00 25.00 0.19" euler="0 0 -0.14" rgba="0.2 0.5 0.9 1" contype="1" conaffinity="1" friction="1 0.005 0.0001" />
            <geom name="terrain_box_27" type="box" size="0.5 0.75 0.46" pos="10.00 30.00 0.46" euler="0 0 0.16" rgba="0.9 0.3 0.3 1" contype="1" conaffinity="1" friction="1 0.005 0.0001" />
            <geom name="terrain_box_28" type="box" size="0.5 0.75 0.38" pos="15.00 -30.00 0.38" euler="0 0 -0.40" rgba="0.95 0.75 0.2 1" contype="1" conaffinity="1" friction="1 0.005 0.0001" />
            <geom name="terrain_box_29" type="box" size="0.5 0.75 0.38" pos="15.00 -25.00 0.38" euler="0 0 -0.35" rgba="0.95 0.75 0.2 1" contype="1" conaffinity="1" friction="1 0.005 0.0001" />
            <geom name="terrain_box_30" type="box" size="0.5 0.75 0.38" pos="15.00 -20.00 0.38" euler="0 0 0.24" rgba="0.95 0.75 0.2 1" contype="1" conaffinity="1" friction="1 0.005 0.0001" />
            <geom name="terrain_box_31" type="box" size="0.5 0.75 0.19" pos="15.00 -15.00 0.19" euler="0 0 0.13" rgba="0.2 0.5 0.9 1" contype="1" conaffinity="1" friction="1 0.005 0.0001" />
            <geom name="terrain_box_32" type="box" size="0.5 0.75 0.29" pos="15.00 -10.00 0.29" euler="0 0 0.04" rgba="0.2 0.8 0.4 1" contype="1" conaffinity="1" friction="1 0.005 0.0001" />
            <geom name="terrain_box_33" type="box" size="0.5 0.75 0.29" pos="15.00 -5.00 0.29" euler="0 0 -0.40" rgba="0.2 0.8 0.4 1" contype="1" conaffinity="1" friction="1 0.005 0.0001" />
            <geom name="terrain_box_34" type="box" size="0.5 0.75 0.46" pos="15.00 0.00 0.46" euler="0 0 -0.28" rgba="0.9 0.3 0.3 1" contype="1" conaffinity="1" friction="1 0.005 0.0001" />
            <geom name="terrain_box_35" type="box" size="0.5 0.75 0.29" pos="15.00 5.00 0.29" euler="0 0 0.22" rgba="0.2 0.8 0.4 1" contype="1" conaffinity="1" friction="1 0.005 0.0001" />
            <geom name="terrain_box_36" type="box" size="0.5 0.75 0.19" pos="15.00 10.00 0.19" euler="0 0 -0.33" rgba="0.2 0.5 0.9 1" contype="1" conaffinity="1" friction="1 0.005 0.0001" />
            <geom name="terrain_box_37" type="box" size="0.5 0.75 0.19" pos="15.00 15.00 0.19" euler="0 0 0.37" rgba="0.2 0.5 0.9 1" contype="1" conaffinity="1" friction="1 0.005 0.0001" />
            <geom name="terrain_box_38" type="box" size="0.5 0.75 0.46" pos="15.00 20.00 0.46" euler="0 0 -0.28" rgba="0.9 0.3 0.3 1" contype="1" conaffinity="1" friction="1 0.005 0.0001" />
            <geom name="terrain_box_39" type="box" size="0.5 0.75 0.29" pos="15.00 25.00 0.29" euler="0 0 0.50" rgba="0.2 0.8 0.4 1" contype="1" conaffinity="1" friction="1 0.005 0.0001" />
            <geom name="terrain_box_40" type="box" size="0.5 0.75 0.38" pos="15.00 30.00 0.38" euler="0 0 -0.34" rgba="0.95 0.75 0.2 1" contype="1" conaffinity="1" friction="1 0.005 0.0001" />
            <geom name="terrain_box_41" type="box" size="0.5 0.75 0.46" pos="20.00 -30.00 0.46" euler="0 0 -0.13" rgba="0.9 0.3 0.3 1" contype="1" conaffinity="1" friction="1 0.005 0.0001" />
            <geom name="terrain_box_42" type="box" size="0.5 0.75 0.46" pos="20.00 -25.00 0.46" euler="0 0 -0.43" rgba="0.9 0.3 0.3 1" contype="1" conaffinity="1" friction="1 0.005 0.0001" />
            <geom name="terrain_box_43" type="box" size="0.5 0.75 0.29" pos="20.00 -20.00 0.29" euler="0 0 -0.30" rgba="0.2 0.8 0.4 1" contype="1" conaffinity="1" friction="1 0.005 0.0001" />
            <geom name="terrain_box_44" type="box" size="0.5 0.75 0.38" pos="20.00 -15.00 0.38" euler="0 0 0.30" rgba="0.95 0.75 0.2 1" contype="1" conaffinity="1" friction="1 0.005 0.0001" />
            <geom name="terrain_box_45" type="box" size="0.5 0.75 0.46" pos="20.00 -10.00 0.46" euler="0 0 0.48" rgba="0.9 0.3 0.3 1" contype="1" conaffinity="1" friction="1 0.005 0.0001" />
            <geom name="terrain_box_46" type="box" size="0.5 0.75 0.46" pos="20.00 -5.00 0.46" euler="0 0 -0.17" rgba="0.9 0.3 0.3 1" contype="1" conaffinity="1" friction="1 0.005 0.0001" />
            <geom name="terrain_box_47" type="box" size="0.5 0.75 0.29" pos="20.00 0.00 0.29" euler="0 0 0.01" rgba="0.2 0.8 0.4 1" contype="1" conaffinity="1" friction="1 0.005 0.0001" />
            <geom name="terrain_box_48" type="box" size="0.5 0.75 0.19" pos="20.00 5.00 0.19" euler="0 0 0.31" rgba="0.2 0.5 0.9 1" contype="1" conaffinity="1" friction="1 0.005 0.0001" />
            <geom name="terrain_box_49" type="box" size="0.5 0.75 0.19" pos="20.00 10.00 0.19" euler="0 0 -0.42" rgba="0.2 0.5 0.9 1" contype="1" conaffinity="1" friction="1 0.005 0.0001" />
            <geom name="terrain_box_50" type="box" size="0.5 0.75 0.29" pos="20.00 15.00 0.29" euler="0 0 0.35" rgba="0.2 0.8 0.4 1" contype="1" conaffinity="1" friction="1 0.005 0.0001" />
            <geom name="terrain_box_51" type="box" size="0.5 0.75 0.46" pos="20.00 20.00 0.46" euler="0 0 0.12" rgba="0.9 0.3 0.3 1" contype="1" conaffinity="1" friction="1 0.005 0.0001" />
            <geom name="terrain_box_52" type="box" size="0.5 0.75 0.46" pos="20.00 25.00 0.46" euler="0 0 -0.14" rgba="0.9 0.3 0.3 1" contype="1" conaffinity="1" friction="1 0.005 0.0001" />
            <geom name="terrain_box_53" type="box" size="0.5 0.75 0.46" pos="20.00 30.00 0.46" euler="0 0 0.03" rgba="0.9 0.3 0.3 1" contype="1" conaffinity="1" friction="1 0.005 0.0001" />
            <geom name="terrain_box_54" type="box" size="0.5 0.75 0.19" pos="25.00 -30.00 0.19" euler="0 0 0.22" rgba="0.2 0.5 0.9 1" contype="1" conaffinity="1" friction="1 0.005 0.0001" />
            <geom name="terrain_box_55" type="box" size="0.5 0.75 0.19" pos="25.00 -25.00 0.19" euler="0 0 0.22" rgba="0.2 0.5 0.9 1" contype="1" conaffinity="1" friction="1 0.005 0.0001" />
            <geom name="terrain_box_56" type="box" size="0.5 0.75 0.38" pos="25.00 -20.00 0.38" euler="0 0 0.32" rgba="0.95 0.75 0.2 1" contype="1" conaffinity="1" friction="1 0.005 0.0001" />
            <geom name="terrain_box_57" type="box" size="0.5 0.75 0.38" pos="25.00 -15.00 0.38" euler="0 0 -0.47" rgba="0.95 0.75 0.2 1" contype="1" conaffinity="1" friction="1 0.005 0.0001" />
            <geom name="terrain_box_58" type="box" size="0.5 0.75 0.46" pos="25.00 -10.00 0.46" euler="0 0 -0.41" rgba="0.9 0.3 0.3 1" contype="1" conaffinity="1" friction="1 0.005 0.0001" />
            <geom name="terrain_box_59" type="box" size="0.5 0.75 0.19" pos="25.00 -5.00 0.19" euler="0 0 0.54" rgba="0.2 0.5 0.9 1" contype="1" conaffinity="1" friction="1 0.005 0.0001" />
            <geom name="terrain_box_60" type="box" size="0.5 0.75 0.38" pos="25.00 0.00 0.38" euler="0 0 0.57" rgba="0.95 0.75 0.2 1" contype="1" conaffinity="1" friction="1 0.005 0.0001" />
            <geom name="terrain_box_61" type="box" size="0.5 0.75 0.29" pos="25.00 5.00 0.29" euler="0 0 0.01" rgba="0.2 0.8 0.4 1" contype="1" conaffinity="1" friction="1 0.005 0.0001" />
            <geom name="terrain_box_62" type="box" size="0.5 0.75 0.19" pos="25.00 10.00 0.19" euler="0 0 0.44" rgba="0.2 0.5 0.9 1" contype="1" conaffinity="1" friction="1 0.005 0.0001" />
            <geom name="terrain_box_63" type="box" size="0.5 0.75 0.38" pos="25.00 15.00 0.38" euler="0 0 0.41" rgba="0.95 0.75 0.2 1" contype="1" conaffinity="1" friction="1 0.005 0.0001" />
            <geom name="terrain_box_64" type="box" size="0.5 0.75 0.29" pos="25.00 20.00 0.29" euler="0 0 -0.42" rgba="0.2 0.8 0.4 1" contype="1" conaffinity="1" friction="1 0.005 0.0001" />
            <geom name="terrain_box_65" type="box" size="0.5 0.75 0.29" pos="25.00 25.00 0.29" euler="0 0 0.05" rgba="0.2 0.8 0.4 1" contype="1" conaffinity="1" friction="1 0.005 0.0001" />
            <geom name="terrain_box_66" type="box" size="0.5 0.75 0.19" pos="25.00 30.00 0.19" euler="0 0 0.12" rgba="0.2 0.5 0.9 1" contype="1" conaffinity="1" friction="1 0.005 0.0001" />
            <geom name="terrain_box_67" type="box" size="0.5 0.75 0.46" pos="30.00 -30.00 0.46" euler="0 0 -0.58" rgba="0.9 0.3 0.3 1" contype="1" conaffinity="1" friction="1 0.005 0.0001" />
            <geom name="terrain_box_68" type="box" size="0.5 0.75 0.38" pos="30.00 -25.00 0.38" euler="0 0 0.45" rgba="0.95 0.75 0.2 1" contype="1" conaffinity="1" friction="1 0.005 0.0001" />
            <geom name="terrain_box_69" type="box" size="0.5 0.75 0.38" pos="30.00 -20.00 0.38" euler="0 0 -0.31" rgba="0.95 0.75 0.2 1" contype="1" conaffinity="1" friction="1 0.005 0.0001" />
            <geom name="terrain_box_70" type="box" size="0.5 0.75 0.29" pos="30.00 -15.00 0.29" euler="0 0 0.45" rgba="0.2 0.8 0.4 1" contype="1" conaffinity="1" friction="1 0.005 0.0001" />
            <geom name="terrain_box_71" type="box" size="0.5 0.75 0.19" pos="30.00 -10.00 0.19" euler="0 0 -0.50" rgba="0.2 0.5 0.9 1" contype="1" conaffinity="1" friction="1 0.005 0.0001" />
            <geom name="terrain_box_72" type="box" size="0.5 0.75 0.46" pos="30.00 -5.00 0.46" euler="0 0 0.38" rgba="0.9 0.3 0.3 1" contype="1" conaffinity="1" friction="1 0.005 0.0001" />
            <geom name="terrain_box_73" type="box" size="0.5 0.75 0.29" pos="30.00 0.00 0.29" euler="0 0 -0.45" rgba="0.2 0.8 0.4 1" contype="1" conaffinity="1" friction="1 0.005 0.0001" />
            <geom name="terrain_box_74" type="box" size="0.5 0.75 0.46" pos="30.00 5.00 0.46" euler="0 0 0.54" rgba="0.9 0.3 0.3 1" contype="1" conaffinity="1" friction="1 0.005 0.0001" />
            <geom name="terrain_box_75" type="box" size="0.5 0.75 0.29" pos="30.00 10.00 0.29" euler="0 0 -0.28" rgba="0.2 0.8 0.4 1" contype="1" conaffinity="1" friction="1 0.005 0.0001" />
            <geom name="terrain_box_76" type="box" size="0.5 0.75 0.46" pos="30.00 15.00 0.46" euler="0 0 0.56" rgba="0.9 0.3 0.3 1" contype="1" conaffinity="1" friction="1 0.005 0.0001" />
            <geom name="terrain_box_77" type="box" size="0.5 0.75 0.29" pos="30.00 20.00 0.29" euler="0 0 0.26" rgba="0.2 0.8 0.4 1" contype="1" conaffinity="1" friction="1 0.005 0.0001" />
            <geom name="terrain_box_78" type="box" size="0.5 0.75 0.46" pos="30.00 25.00 0.46" euler="0 0 0.59" rgba="0.9 0.3 0.3 1" contype="1" conaffinity="1" friction="1 0.005 0.0001" />
            <geom name="terrain_box_79" type="box" size="0.5 0.75 0.38" pos="30.00 30.00 0.38" euler="0 0 -0.07" rgba="0.95 0.75 0.2 1" contype="1" conaffinity="1" friction="1 0.005 0.0001" />
            <geom name="terrain_box_80" type="box" size="0.5 0.75 0.46" pos="35.00 -30.00 0.46" euler="0 0 -0.45" rgba="0.9 0.3 0.3 1" contype="1" conaffinity="1" friction="1 0.005 0.0001" />
            <geom name="terrain_box_81" type="box" size="0.5 0.75 0.29" pos="35.00 -25.00 0.29" euler="0 0 -0.52" rgba="0.2 0.8 0.4 1" contype="1" conaffinity="1" friction="1 0.005 0.0001" />
            <geom name="terrain_box_82" type="box" size="0.5 0.75 0.19" pos="35.00 -20.00 0.19" euler="0 0 0.11" rgba="0.2 0.5 0.9 1" contype="1" conaffinity="1" friction="1 0.005 0.0001" />
            <geom name="terrain_box_83" type="box" size="0.5 0.75 0.29" pos="35.00 -15.00 0.29" euler="0 0 0.11" rgba="0.2 0.8 0.4 1" contype="1" conaffinity="1" friction="1 0.005 0.0001" />
            <geom name="terrain_box_84" type="box" size="0.5 0.75 0.19" pos="35.00 -10.00 0.19" euler="0 0 -0.51" rgba="0.2 0.5 0.9 1" contype="1" conaffinity="1" friction="1 0.005 0.0001" />
            <geom name="terrain_box_85" type="box" size="0.5 0.75 0.19" pos="35.00 -5.00 0.19" euler="0 0 -0.33" rgba="0.2 0.5 0.9 1" contype="1" conaffinity="1" friction="1 0.005 0.0001" />
            <geom name="terrain_box_86" type="box" size="0.5 0.75 0.19" pos="35.00 0.00 0.19" euler="0 0 0.43" rgba="0.2 0.5 0.9 1" contype="1" conaffinity="1" friction="1 0.005 0.0001" />
            <geom name="terrain_box_87" type="box" size="0.5 0.75 0.19" pos="35.00 5.00 0.19" euler="0 0 0.02" rgba="0.2 0.5 0.9 1" contype="1" conaffinity="1" friction="1 0.005 0.0001" />
            <geom name="terrain_box_88" type="box" size="0.5 0.75 0.38" pos="35.00 10.00 0.38" euler="0 0 0.20" rgba="0.95 0.75 0.2 1" contype="1" conaffinity="1" friction="1 0.005 0.0001" />
            <geom name="terrain_box_89" type="box" size="0.5 0.75 0.29" pos="35.00 15.00 0.29" euler="0 0 0.05" rgba="0.2 0.8 0.4 1" contype="1" conaffinity="1" friction="1 0.005 0.0001" />
            <geom name="terrain_box_90" type="box" size="0.5 0.75 0.46" pos="35.00 20.00 0.46" euler="0 0 -0.31" rgba="0.9 0.3 0.3 1" contype="1" conaffinity="1" friction="1 0.005 0.0001" />
            <geom name="terrain_box_91" type="box" size="0.5 0.75 0.46" pos="35.00 25.00 0.46" euler="0 0 0.37" rgba="0.9 0.3 0.3 1" contype="1" conaffinity="1" friction="1 0.005 0.0001" />
            <geom name="terrain_box_92" type="box" size="0.5 0.75 0.29" pos="35.00 30.00 0.29" euler="0 0 -0.49" rgba="0.2 0.8 0.4 1" contype="1" conaffinity="1" friction="1 0.005 0.0001" />
            <geom name="terrain_box_93" type="box" size="0.5 0.75 0.46" pos="40.00 -30.00 0.46" euler="0 0 -0.17" rgba="0.9 0.3 0.3 1" contype="1" conaffinity="1" friction="1 0.005 0.0001" />
            <geom name="terrain_box_94" type="box" size="0.5 0.75 0.46" pos="40.00 -25.00 0.46" euler="0 0 -0.04" rgba="0.9 0.3 0.3 1" contype="1" conaffinity="1" friction="1 0.005 0.0001" />
            <geom name="terrain_box_95" type="box" size="0.5 0.75 0.19" pos="40.00 -20.00 0.19" euler="0 0 0.21" rgba="0.2 0.5 0.9 1" contype="1" conaffinity="1" friction="1 0.005 0.0001" />
            <geom name="terrain_box_96" type="box" size="0.5 0.75 0.19" pos="40.00 -15.00 0.19" euler="0 0 -0.53" rgba="0.2 0.5 0.9 1" contype="1" conaffinity="1" friction="1 0.005 0.0001" />
            <geom name="terrain_box_97" type="box" size="0.5 0.75 0.38" pos="40.00 -10.00 0.38" euler="0 0 0.36" rgba="0.95 0.75 0.2 1" contype="1" conaffinity="1" friction="1 0.005 0.0001" />
            <geom name="terrain_box_98" type="box" size="0.5 0.75 0.19" pos="40.00 -5.00 0.19" euler="0 0 -0.30" rgba="0.2 0.5 0.9 1" contype="1" conaffinity="1" friction="1 0.005 0.0001" />
            <geom name="terrain_box_99" type="box" size="0.5 0.75 0.29" pos="40.00 0.00 0.29" euler="0 0 0.04" rgba="0.2 0.8 0.4 1" contype="1" conaffinity="1" friction="1 0.005 0.0001" />
            <geom name="terrain_box_100" type="box" size="0.5 0.75 0.29" pos="40.00 5.00 0.29" euler="0 0 -0.09" rgba="0.2 0.8 0.4 1" contype="1" conaffinity="1" friction="1 0.005 0.0001" />
            <geom name="terrain_box_101" type="box" size="0.5 0.75 0.38" pos="40.00 10.00 0.38" euler="0 0 -0.04" rgba="0.95 0.75 0.2 1" contype="1" conaffinity="1" friction="1 0.005 0.0001" />
            <geom name="terrain_box_102" type="box" size="0.5 0.75 0.19" pos="40.00 15.00 0.19" euler="0 0 -0.07" rgba="0.2 0.5 0.9 1" contype="1" conaffinity="1" friction="1 0.005 0.0001" />
            <geom name="terrain_box_103" type="box" size="0.5 0.75 0.19" pos="40.00 20.00 0.19" euler="0 0 -0.54" rgba="0.2 0.5 0.9 1" contype="1" conaffinity="1" friction="1 0.005 0.0001" />
            <geom name="terrain_box_104" type="box" size="0.5 0.75 0.19" pos="40.00 25.00 0.19" euler="0 0 0.56" rgba="0.2 0.5 0.9 1" contype="1" conaffinity="1" friction="1 0.005 0.0001" />
            <geom name="terrain_box_105" type="box" size="0.5 0.75 0.29" pos="40.00 30.00 0.29" euler="0 0 -0.40" rgba="0.2 0.8 0.4 1" contype="1" conaffinity="1" friction="1 0.005 0.0001" />
            <geom name="terrain_box_106" type="box" size="0.5 0.75 0.46" pos="45.00 -30.00 0.46" euler="0 0 -0.02" rgba="0.9 0.3 0.3 1" contype="1" conaffinity="1" friction="1 0.005 0.0001" />
            <geom name="terrain_box_107" type="box" size="0.5 0.75 0.46" pos="45.00 -25.00 0.46" euler="0 0 0.48" rgba="0.9 0.3 0.3 1" contype="1" conaffinity="1" friction="1 0.005 0.0001" />
            <geom name="terrain_box_108" type="box" size="0.5 0.75 0.29" pos="45.00 -20.00 0.29" euler="0 0 -0.15" rgba="0.2 0.8 0.4 1" contype="1" conaffinity="1" friction="1 0.005 0.0001" />
            <geom name="terrain_box_109" type="box" size="0.5 0.75 0.46" pos="45.00 -15.00 0.46" euler="0 0 -0.28" rgba="0.9 0.3 0.3 1" contype="1" conaffinity="1" friction="1 0.005 0.0001" />
            <geom name="terrain_box_110" type="box" size="0.5 0.75 0.46" pos="45.00 -10.00 0.46" euler="0 0 -0.26" rgba="0.9 0.3 0.3 1" contype="1" conaffinity="1" friction="1 0.005 0.0001" />
            <geom name="terrain_box_111" type="box" size="0.5 0.75 0.46" pos="45.00 -5.00 0.46" euler="0 0 -0.41" rgba="0.9 0.3 0.3 1" contype="1" conaffinity="1" friction="1 0.005 0.0001" />
            <geom name="terrain_box_112" type="box" size="0.5 0.75 0.38" pos="45.00 0.00 0.38" euler="0 0 -0.34" rgba="0.95 0.75 0.2 1" contype="1" conaffinity="1" friction="1 0.005 0.0001" />
            <geom name="terrain_box_113" type="box" size="0.5 0.75 0.19" pos="45.00 5.00 0.19" euler="0 0 0.10" rgba="0.2 0.5 0.9 1" contype="1" conaffinity="1" friction="1 0.005 0.0001" />
            <geom name="terrain_box_114" type="box" size="0.5 0.75 0.19" pos="45.00 10.00 0.19" euler="0 0 0.30" rgba="0.2 0.5 0.9 1" contype="1" conaffinity="1" friction="1 0.005 0.0001" />
            <geom name="terrain_box_115" type="box" size="0.5 0.75 0.19" pos="45.00 15.00 0.19" euler="0 0 -0.54" rgba="0.2 0.5 0.9 1" contype="1" conaffinity="1" friction="1 0.005 0.0001" />
            <geom name="terrain_box_116" type="box" size="0.5 0.75 0.46" pos="45.00 20.00 0.46" euler="0 0 0.00" rgba="0.9 0.3 0.3 1" contype="1" conaffinity="1" friction="1 0.005 0.0001" />
            <geom name="terrain_box_117" type="box" size="0.5 0.75 0.29" pos="45.00 25.00 0.29" euler="0 0 -0.53" rgba="0.2 0.8 0.4 1" contype="1" conaffinity="1" friction="1 0.005 0.0001" />
            <geom name="terrain_box_118" type="box" size="0.5 0.75 0.19" pos="45.00 30.00 0.19" euler="0 0 0.42" rgba="0.2 0.5 0.9 1" contype="1" conaffinity="1" friction="1 0.005 0.0001" />
            <geom name="terrain_box_119" type="box" size="0.5 0.75 0.19" pos="50.00 -30.00 0.19" euler="0 0 0.11" rgba="0.2 0.5 0.9 1" contype="1" conaffinity="1" friction="1 0.005 0.0001" />
            <geom name="terrain_box_120" type="box" size="0.5 0.75 0.29" pos="50.00 -25.00 0.29" euler="0 0 -0.12" rgba="0.2 0.8 0.4 1" contype="1" conaffinity="1" friction="1 0.005 0.0001" />
            <geom name="terrain_box_121" type="box" size="0.5 0.75 0.29" pos="50.00 -20.00 0.29" euler="0 0 0.09" rgba="0.2 0.8 0.4 1" contype="1" conaffinity="1" friction="1 0.005 0.0001" />
            <geom name="terrain_box_122" type="box" size="0.5 0.75 0.19" pos="50.00 -15.00 0.19" euler="0 0 0.14" rgba="0.2 0.5 0.9 1" contype="1" conaffinity="1" friction="1 0.005 0.0001" />
            <geom name="terrain_box_123" type="box" size="0.5 0.75 0.46" pos="50.00 -10.00 0.46" euler="0 0 0.19" rgba="0.9 0.3 0.3 1" contype="1" conaffinity="1" friction="1 0.005 0.0001" />
            <geom name="terrain_box_124" type="box" size="0.5 0.75 0.38" pos="50.00 -5.00 0.38" euler="0 0 0.52" rgba="0.95 0.75 0.2 1" contype="1" conaffinity="1" friction="1 0.005 0.0001" />
            <geom name="terrain_box_125" type="box" size="0.5 0.75 0.29" pos="50.00 0.00 0.29" euler="0 0 0.20" rgba="0.2 0.8 0.4 1" contype="1" conaffinity="1" friction="1 0.005 0.0001" />
            <geom name="terrain_box_126" type="box" size="0.5 0.75 0.38" pos="50.00 5.00 0.38" euler="0 0 -0.31" rgba="0.95 0.75 0.2 1" contype="1" conaffinity="1" friction="1 0.005 0.0001" />
            <geom name="terrain_box_127" type="box" size="0.5 0.75 0.46" pos="50.00 10.00 0.46" euler="0 0 -0.44" rgba="0.9 0.3 0.3 1" contype="1" conaffinity="1" friction="1 0.005 0.0001" />
            <geom name="terrain_box_128" type="box" size="0.5 0.75 0.38" pos="50.00 15.00 0.38" euler="0 0 -0.05" rgba="0.95 0.75 0.2 1" contype="1" conaffinity="1" friction="1 0.005 0.0001" />
            <geom name="terrain_box_129" type="box" size="0.5 0.75 0.19" pos="50.00 20.00 0.19" euler="0 0 -0.59" rgba="0.2 0.5 0.9 1" contype="1" conaffinity="1" friction="1 0.005 0.0001" />
            <geom name="terrain_box_130" type="box" size="0.5 0.75 0.19" pos="50.00 25.00 0.19" euler="0 0 -0.51" rgba="0.2 0.5 0.9 1" contype="1" conaffinity="1" friction="1 0.005 0.0001" />
            <geom name="terrain_box_131" type="box" size="0.5 0.75 0.29" pos="50.00 30.00 0.29" euler="0 0 0.01" rgba="0.2 0.8 0.4 1" contype="1" conaffinity="1" friction="1 0.005 0.0001" />
            <geom name="terrain_box_132" type="box" size="0.5 0.75 0.29" pos="55.00 -30.00 0.29" euler="0 0 0.52" rgba="0.2 0.8 0.4 1" contype="1" conaffinity="1" friction="1 0.005 0.0001" />
            <geom name="terrain_box_133" type="box" size="0.5 0.75 0.19" pos="55.00 -25.00 0.19" euler="0 0 0.46" rgba="0.2 0.5 0.9 1" contype="1" conaffinity="1" friction="1 0.005 0.0001" />
            <geom name="terrain_box_134" type="box" size="0.5 0.75 0.38" pos="55.00 -20.00 0.38" euler="0 0 -0.26" rgba="0.95 0.75 0.2 1" contype="1" conaffinity="1" friction="1 0.005 0.0001" />
            <geom name="terrain_box_135" type="box" size="0.5 0.75 0.46" pos="55.00 -15.00 0.46" euler="0 0 0.40" rgba="0.9 0.3 0.3 1" contype="1" conaffinity="1" friction="1 0.005 0.0001" />
            <geom name="terrain_box_136" type="box" size="0.5 0.75 0.38" pos="55.00 -10.00 0.38" euler="0 0 0.13" rgba="0.95 0.75 0.2 1" contype="1" conaffinity="1" friction="1 0.005 0.0001" />
            <geom name="terrain_box_137" type="box" size="0.5 0.75 0.19" pos="55.00 -5.00 0.19" euler="0 0 0.20" rgba="0.2 0.5 0.9 1" contype="1" conaffinity="1" friction="1 0.005 0.0001" />
            <geom name="terrain_box_138" type="box" size="0.5 0.75 0.38" pos="55.00 0.00 0.38" euler="0 0 0.52" rgba="0.95 0.75 0.2 1" contype="1" conaffinity="1" friction="1 0.005 0.0001" />
            <geom name="terrain_box_139" type="box" size="0.5 0.75 0.19" pos="55.00 5.00 0.19" euler="0 0 0.53" rgba="0.2 0.5 0.9 1" contype="1" conaffinity="1" friction="1 0.005 0.0001" />
            <geom name="terrain_box_140" type="box" size="0.5 0.75 0.29" pos="55.00 10.00 0.29" euler="0 0 -0.28" rgba="0.2 0.8 0.4 1" contype="1" conaffinity="1" friction="1 0.005 0.0001" />
            <geom name="terrain_box_141" type="box" size="0.5 0.75 0.19" pos="55.00 15.00 0.19" euler="0 0 0.29" rgba="0.2 0.5 0.9 1" contype="1" conaffinity="1" friction="1 0.005 0.0001" />
            <geom name="terrain_box_142" type="box" size="0.5 0.75 0.29" pos="55.00 20.00 0.29" euler="0 0 -0.27" rgba="0.2 0.8 0.4 1" contype="1" conaffinity="1" friction="1 0.005 0.0001" />
            <geom name="terrain_box_143" type="box" size="0.5 0.75 0.29" pos="55.00 25.00 0.29" euler="0 0 0.26" rgba="0.2 0.8 0.4 1" contype="1" conaffinity="1" friction="1 0.005 0.0001" />
            <geom name="terrain_box_144" type="box" size="0.5 0.75 0.29" pos="55.00 30.00 0.29" euler="0 0 0.22" rgba="0.2 0.8 0.4 1" contype="1" conaffinity="1" friction="1 0.005 0.0001" />
            <geom name="terrain_box_145" type="box" size="0.5 0.75 0.38" pos="60.00 -30.00 0.38" euler="0 0 0.01" rgba="0.95 0.75 0.2 1" contype="1" conaffinity="1" friction="1 0.005 0.0001" />
            <geom name="terrain_box_146" type="box" size="0.5 0.75 0.38" pos="60.00 -25.00 0.38" euler="0 0 0.49" rgba="0.95 0.75 0.2 1" contype="1" conaffinity="1" friction="1 0.005 0.0001" />
            <geom name="terrain_box_147" type="box" size="0.5 0.75 0.19" pos="60.00 -20.00 0.19" euler="0 0 -0.49" rgba="0.2 0.5 0.9 1" contype="1" conaffinity="1" friction="1 0.005 0.0001" />
            <geom name="terrain_box_148" type="box" size="0.5 0.75 0.46" pos="60.00 -15.00 0.46" euler="0 0 0.40" rgba="0.9 0.3 0.3 1" contype="1" conaffinity="1" friction="1 0.005 0.0001" />
            <geom name="terrain_box_149" type="box" size="0.5 0.75 0.19" pos="60.00 -10.00 0.19" euler="0 0 -0.60" rgba="0.2 0.5 0.9 1" contype="1" conaffinity="1" friction="1 0.005 0.0001" />
            <geom name="terrain_box_150" type="box" size="0.5 0.75 0.29" pos="60.00 -5.00 0.29" euler="0 0 0.16" rgba="0.2 0.8 0.4 1" contype="1" conaffinity="1" friction="1 0.005 0.0001" />
            <geom name="terrain_box_151" type="box" size="0.5 0.75 0.38" pos="60.00 0.00 0.38" euler="0 0 -0.41" rgba="0.95 0.75 0.2 1" contype="1" conaffinity="1" friction="1 0.005 0.0001" />
            <geom name="terrain_box_152" type="box" size="0.5 0.75 0.46" pos="60.00 5.00 0.46" euler="0 0 0.06" rgba="0.9 0.3 0.3 1" contype="1" conaffinity="1" friction="1 0.005 0.0001" />
            <geom name="terrain_box_153" type="box" size="0.5 0.75 0.46" pos="60.00 10.00 0.46" euler="0 0 0.07" rgba="0.9 0.3 0.3 1" contype="1" conaffinity="1" friction="1 0.005 0.0001" />
            <geom name="terrain_box_154" type="box" size="0.5 0.75 0.19" pos="60.00 15.00 0.19" euler="0 0 -0.51" rgba="0.2 0.5 0.9 1" contype="1" conaffinity="1" friction="1 0.005 0.0001" />
            <geom name="terrain_box_155" type="box" size="0.5 0.75 0.29" pos="60.00 20.00 0.29" euler="0 0 0.05" rgba="0.2 0.8 0.4 1" contype="1" conaffinity="1" friction="1 0.005 0.0001" />
            <geom name="terrain_box_156" type="box" size="0.5 0.75 0.38" pos="60.00 25.00 0.38" euler="0 0 0.10" rgba="0.95 0.75 0.2 1" contype="1" conaffinity="1" friction="1 0.005 0.0001" />
            <geom name="terrain_box_157" type="box" size="0.5 0.75 0.29" pos="60.00 30.00 0.29" euler="0 0 -0.08" rgba="0.2 0.8 0.4 1" contype="1" conaffinity="1" friction="1 0.005 0.0001" />
            <geom name="terrain_box_158" type="box" size="0.5 0.75 0.19" pos="65.00 -30.00 0.19" euler="0 0 -0.23" rgba="0.2 0.5 0.9 1" contype="1" conaffinity="1" friction="1 0.005 0.0001" />
            <geom name="terrain_box_159" type="box" size="0.5 0.75 0.19" pos="65.00 -25.00 0.19" euler="0 0 0.48" rgba="0.2 0.5 0.9 1" contype="1" conaffinity="1" friction="1 0.005 0.0001" />
            <geom name="terrain_box_160" type="box" size="0.5 0.75 0.29" pos="65.00 -20.00 0.29" euler="0 0 0.22" rgba="0.2 0.8 0.4 1" contype="1" conaffinity="1" friction="1 0.005 0.0001" />
            <geom name="terrain_box_161" type="box" size="0.5 0.75 0.19" pos="65.00 -15.00 0.19" euler="0 0 -0.18" rgba="0.2 0.5 0.9 1" contype="1" conaffinity="1" friction="1 0.005 0.0001" />
            <geom name="terrain_box_162" type="box" size="0.5 0.75 0.46" pos="65.00 -10.00 0.46" euler="0 0 0.57" rgba="0.9 0.3 0.3 1" contype="1" conaffinity="1" friction="1 0.005 0.0001" />
            <geom name="terrain_box_163" type="box" size="0.5 0.75 0.29" pos="65.00 -5.00 0.29" euler="0 0 0.51" rgba="0.2 0.8 0.4 1" contype="1" conaffinity="1" friction="1 0.005 0.0001" />
            <geom name="terrain_box_164" type="box" size="0.5 0.75 0.29" pos="65.00 0.00 0.29" euler="0 0 0.44" rgba="0.2 0.8 0.4 1" contype="1" conaffinity="1" friction="1 0.005 0.0001" />
            <geom name="terrain_box_165" type="box" size="0.5 0.75 0.29" pos="65.00 5.00 0.29" euler="0 0 0.46" rgba="0.2 0.8 0.4 1" contype="1" conaffinity="1" friction="1 0.005 0.0001" />
            <geom name="terrain_box_166" type="box" size="0.5 0.75 0.19" pos="65.00 10.00 0.19" euler="0 0 -0.38" rgba="0.2 0.5 0.9 1" contype="1" conaffinity="1" friction="1 0.005 0.0001" />
            <geom name="terrain_box_167" type="box" size="0.5 0.75 0.38" pos="65.00 15.00 0.38" euler="0 0 0.34" rgba="0.95 0.75 0.2 1" contype="1" conaffinity="1" friction="1 0.005 0.0001" />
            <geom name="terrain_box_168" type="box" size="0.5 0.75 0.46" pos="65.00 20.00 0.46" euler="0 0 0.36" rgba="0.9 0.3 0.3 1" contype="1" conaffinity="1" friction="1 0.005 0.0001" />
            <geom name="terrain_box_169" type="box" size="0.5 0.75 0.29" pos="65.00 25.00 0.29" euler="0 0 -0.28" rgba="0.2 0.8 0.4 1" contype="1" conaffinity="1" friction="1 0.005 0.0001" />
            <geom name="terrain_box_170" type="box" size="0.5 0.75 0.19" pos="65.00 30.00 0.19" euler="0 0 -0.14" rgba="0.2 0.5 0.9 1" contype="1" conaffinity="1" friction="1 0.005 0.0001" />
            <geom name="terrain_box_171" type="box" size="0.5 0.75 0.19" pos="70.00 -30.00 0.19" euler="0 0 0.43" rgba="0.2 0.5 0.9 1" contype="1" conaffinity="1" friction="1 0.005 0.0001" />
            <geom name="terrain_box_172" type="box" size="0.5 0.75 0.29" pos="70.00 -25.00 0.29" euler="0 0 -0.36" rgba="0.2 0.8 0.4 1" contype="1" conaffinity="1" friction="1 0.005 0.0001" />
            <geom name="terrain_box_173" type="box" size="0.5 0.75 0.46" pos="70.00 -20.00 0.46" euler="0 0 -0.18" rgba="0.9 0.3 0.3 1" contype="1" conaffinity="1" friction="1 0.005 0.0001" />
            <geom name="terrain_box_174" type="box" size="0.5 0.75 0.29" pos="70.00 -15.00 0.29" euler="0 0 -0.33" rgba="0.2 0.8 0.4 1" contype="1" conaffinity="1" friction="1 0.005 0.0001" />
            <geom name="terrain_box_175" type="box" size="0.5 0.75 0.29" pos="70.00 -10.00 0.29" euler="0 0 -0.12" rgba="0.2 0.8 0.4 1" contype="1" conaffinity="1" friction="1 0.005 0.0001" />
            <geom name="terrain_box_176" type="box" size="0.5 0.75 0.38" pos="70.00 -5.00 0.38" euler="0 0 0.44" rgba="0.95 0.75 0.2 1" contype="1" conaffinity="1" friction="1 0.005 0.0001" />
            <geom name="terrain_box_177" type="box" size="0.5 0.75 0.38" pos="70.00 0.00 0.38" euler="0 0 -0.18" rgba="0.95 0.75 0.2 1" contype="1" conaffinity="1" friction="1 0.005 0.0001" />
            <geom name="terrain_box_178" type="box" size="0.5 0.75 0.46" pos="70.00 5.00 0.46" euler="0 0 0.22" rgba="0.9 0.3 0.3 1" contype="1" conaffinity="1" friction="1 0.005 0.0001" />
            <geom name="terrain_box_179" type="box" size="0.5 0.75 0.38" pos="70.00 10.00 0.38" euler="0 0 0.53" rgba="0.95 0.75 0.2 1" contype="1" conaffinity="1" friction="1 0.005 0.0001" />
            <geom name="terrain_box_180" type="box" size="0.5 0.75 0.19" pos="70.00 15.00 0.19" euler="0 0 0.45" rgba="0.2 0.5 0.9 1" contype="1" conaffinity="1" friction="1 0.005 0.0001" />
            <geom name="terrain_box_181" type="box" size="0.5 0.75 0.38" pos="70.00 20.00 0.38" euler="0 0 -0.39" rgba="0.95 0.75 0.2 1" contype="1" conaffinity="1" friction="1 0.005 0.0001" />
            <geom name="terrain_box_182" type="box" size="0.5 0.75 0.38" pos="70.00 25.00 0.38" euler="0 0 -0.55" rgba="0.95 0.75 0.2 1" contype="1" conaffinity="1" friction="1 0.005 0.0001" />
            <geom name="terrain_box_183" type="box" size="0.5 0.75 0.46" pos="70.00 30.00 0.46" euler="0 0 -0.19" rgba="0.9 0.3 0.3 1" contype="1" conaffinity="1" friction="1 0.005 0.0001" />
            <geom name="terrain_box_184" type="box" size="0.5 0.75 0.38" pos="75.00 -30.00 0.38" euler="0 0 -0.08" rgba="0.95 0.75 0.2 1" contype="1" conaffinity="1" friction="1 0.005 0.0001" />
            <geom name="terrain_box_185" type="box" size="0.5 0.75 0.19" pos="75.00 -25.00 0.19" euler="0 0 -0.14" rgba="0.2 0.5 0.9 1" contype="1" conaffinity="1" friction="1 0.005 0.0001" />
            <geom name="terrain_box_186" type="box" size="0.5 0.75 0.29" pos="75.00 -20.00 0.29" euler="0 0 -0.29" rgba="0.2 0.8 0.4 1" contype="1" conaffinity="1" friction="1 0.005 0.0001" />
            <geom name="terrain_box_187" type="box" size="0.5 0.75 0.46" pos="75.00 -15.00 0.46" euler="0 0 -0.60" rgba="0.9 0.3 0.3 1" contype="1" conaffinity="1" friction="1 0.005 0.0001" />
            <geom name="terrain_box_188" type="box" size="0.5 0.75 0.29" pos="75.00 -10.00 0.29" euler="0 0 -0.16" rgba="0.2 0.8 0.4 1" contype="1" conaffinity="1" friction="1 0.005 0.0001" />
            <geom name="terrain_box_189" type="box" size="0.5 0.75 0.19" pos="75.00 -5.00 0.19" euler="0 0 0.54" rgba="0.2 0.5 0.9 1" contype="1" conaffinity="1" friction="1 0.005 0.0001" />
            <geom name="terrain_box_190" type="box" size="0.5 0.75 0.38" pos="75.00 0.00 0.38" euler="0 0 0.15" rgba="0.95 0.75 0.2 1" contype="1" conaffinity="1" friction="1 0.005 0.0001" />
            <geom name="terrain_box_191" type="box" size="0.5 0.75 0.19" pos="75.00 5.00 0.19" euler="0 0 0.26" rgba="0.2 0.5 0.9 1" contype="1" conaffinity="1" friction="1 0.005 0.0001" />
            <geom name="terrain_box_192" type="box" size="0.5 0.75 0.38" pos="75.00 10.00 0.38" euler="0 0 0.01" rgba="0.95 0.75 0.2 1" contype="1" conaffinity="1" friction="1 0.005 0.0001" />
            <geom name="terrain_box_193" type="box" size="0.5 0.75 0.46" pos="75.00 15.00 0.46" euler="0 0 -0.21" rgba="0.9 0.3 0.3 1" contype="1" conaffinity="1" friction="1 0.005 0.0001" />
            <geom name="terrain_box_194" type="box" size="0.5 0.75 0.38" pos="75.00 20.00 0.38" euler="0 0 0.07" rgba="0.95 0.75 0.2 1" contype="1" conaffinity="1" friction="1 0.005 0.0001" />
            <geom name="terrain_box_195" type="box" size="0.5 0.75 0.29" pos="75.00 25.00 0.29" euler="0 0 -0.10" rgba="0.2 0.8 0.4 1" contype="1" conaffinity="1" friction="1 0.005 0.0001" />
            <geom name="terrain_box_196" type="box" size="0.5 0.75 0.46" pos="75.00 30.00 0.46" euler="0 0 0.21" rgba="0.9 0.3 0.3 1" contype="1" conaffinity="1" friction="1 0.005 0.0001" />
            <geom name="terrain_box_197" type="box" size="0.5 0.75 0.29" pos="80.00 -30.00 0.29" euler="0 0 0.14" rgba="0.2 0.8 0.4 1" contype="1" conaffinity="1" friction="1 0.005 0.0001" />
            <geom name="terrain_box_198" type="box" size="0.5 0.75 0.38" pos="80.00 -25.00 0.38" euler="0 0 -0.11" rgba="0.95 0.75 0.2 1" contype="1" conaffinity="1" friction="1 0.005 0.0001" />
            <geom name="terrain_box_199" type="box" size="0.5 0.75 0.19" pos="80.00 -20.00 0.19" euler="0 0 -0.24" rgba="0.2 0.5 0.9 1" contype="1" conaffinity="1" friction="1 0.005 0.0001" />
            <geom name="terrain_box_200" type="box" size="0.5 0.75 0.29" pos="80.00 -15.00 0.29" euler="0 0 -0.08" rgba="0.2 0.8 0.4 1" contype="1" conaffinity="1" friction="1 0.005 0.0001" />
            <geom name="terrain_box_201" type="box" size="0.5 0.75 0.38" pos="80.00 -10.00 0.38" euler="0 0 -0.04" rgba="0.95 0.75 0.2 1" contype="1" conaffinity="1" friction="1 0.005 0.0001" />
            <geom name="terrain_box_202" type="box" size="0.5 0.75 0.46" pos="80.00 -5.00 0.46" euler="0 0 0.21" rgba="0.9 0.3 0.3 1" contype="1" conaffinity="1" friction="1 0.005 0.0001" />
            <geom name="terrain_box_203" type="box" size="0.5 0.75 0.46" pos="80.00 0.00 0.46" euler="0 0 0.35" rgba="0.9 0.3 0.3 1" contype="1" conaffinity="1" friction="1 0.005 0.0001" />
            <geom name="terrain_box_204" type="box" size="0.5 0.75 0.29" pos="80.00 5.00 0.29" euler="0 0 0.19" rgba="0.2 0.8 0.4 1" contype="1" conaffinity="1" friction="1 0.005 0.0001" />
            <geom name="terrain_box_205" type="box" size="0.5 0.75 0.38" pos="80.00 10.00 0.38" euler="0 0 0.02" rgba="0.95 0.75 0.2 1" contype="1" conaffinity="1" friction="1 0.005 0.0001" />
            <geom name="terrain_box_206" type="box" size="0.5 0.75 0.38" pos="80.00 15.00 0.38" euler="0 0 -0.49" rgba="0.95 0.75 0.2 1" contype="1" conaffinity="1" friction="1 0.005 0.0001" />
            <geom name="terrain_box_207" type="box" size="0.5 0.75 0.29" pos="80.00 20.00 0.29" euler="0 0 0.21" rgba="0.2 0.8 0.4 1" contype="1" conaffinity="1" friction="1 0.005 0.0001" />
            <geom name="terrain_box_208" type="box" size="0.5 0.75 0.29" pos="80.00 25.00 0.29" euler="0 0 0.37" rgba="0.2 0.8 0.4 1" contype="1" conaffinity="1" friction="1 0.005 0.0001" />
            <geom name="terrain_box_209" type="box" size="0.5 0.75 0.29" pos="80.00 30.00 0.29" euler="0 0 -0.57" rgba="0.2 0.8 0.4 1" contype="1" conaffinity="1" friction="1 0.005 0.0001" />
            <geom name="terrain_box_210" type="box" size="0.5 0.75 0.29" pos="85.00 -30.00 0.29" euler="0 0 0.58" rgba="0.2 0.8 0.4 1" contype="1" conaffinity="1" friction="1 0.005 0.0001" />
            <geom name="terrain_box_211" type="box" size="0.5 0.75 0.19" pos="85.00 -25.00 0.19" euler="0 0 -0.05" rgba="0.2 0.5 0.9 1" contype="1" conaffinity="1" friction="1 0.005 0.0001" />
            <geom name="terrain_box_212" type="box" size="0.5 0.75 0.29" pos="85.00 -20.00 0.29" euler="0 0 0.26" rgba="0.2 0.8 0.4 1" contype="1" conaffinity="1" friction="1 0.005 0.0001" />
            <geom name="terrain_box_213" type="box" size="0.5 0.75 0.46" pos="85.00 -15.00 0.46" euler="0 0 -0.01" rgba="0.9 0.3 0.3 1" contype="1" conaffinity="1" friction="1 0.005 0.0001" />
            <geom name="terrain_box_214" type="box" size="0.5 0.75 0.29" pos="85.00 -10.00 0.29" euler="0 0 -0.42" rgba="0.2 0.8 0.4 1" contype="1" conaffinity="1" friction="1 0.005 0.0001" />
            <geom name="terrain_box_215" type="box" size="0.5 0.75 0.19" pos="85.00 -5.00 0.19" euler="0 0 0.47" rgba="0.2 0.5 0.9 1" contype="1" conaffinity="1" friction="1 0.005 0.0001" />
            <geom name="terrain_box_216" type="box" size="0.5 0.75 0.19" pos="85.00 0.00 0.19" euler="0 0 0.33" rgba="0.2 0.5 0.9 1" contype="1" conaffinity="1" friction="1 0.005 0.0001" />
            <geom name="terrain_box_217" type="box" size="0.5 0.75 0.29" pos="85.00 5.00 0.29" euler="0 0 -0.39" rgba="0.2 0.8 0.4 1" contype="1" conaffinity="1" friction="1 0.005 0.0001" />
            <geom name="terrain_box_218" type="box" size="0.5 0.75 0.46" pos="85.00 10.00 0.46" euler="0 0 -0.54" rgba="0.9 0.3 0.3 1" contype="1" conaffinity="1" friction="1 0.005 0.0001" />
            <geom name="terrain_box_219" type="box" size="0.5 0.75 0.29" pos="85.00 15.00 0.29" euler="0 0 0.50" rgba="0.2 0.8 0.4 1" contype="1" conaffinity="1" friction="1 0.005 0.0001" />
            <geom name="terrain_box_220" type="box" size="0.5 0.75 0.19" pos="85.00 20.00 0.19" euler="0 0 -0.05" rgba="0.2 0.5 0.9 1" contype="1" conaffinity="1" friction="1 0.005 0.0001" />
            <geom name="terrain_box_221" type="box" size="0.5 0.75 0.46" pos="85.00 25.00 0.46" euler="0 0 0.20" rgba="0.9 0.3 0.3 1" contype="1" conaffinity="1" friction="1 0.005 0.0001" />
            <geom name="terrain_box_222" type="box" size="0.5 0.75 0.38" pos="85.00 30.00 0.38" euler="0 0 0.54" rgba="0.95 0.75 0.2 1" contype="1" conaffinity="1" friction="1 0.005 0.0001" />
            <geom name="terrain_box_223" type="box" size="0.5 0.75 0.46" pos="90.00 -30.00 0.46" euler="0 0 0.14" rgba="0.9 0.3 0.3 1" contype="1" conaffinity="1" friction="1 0.005 0.0001" />
            <geom name="terrain_box_224" type="box" size="0.5 0.75 0.46" pos="90.00 -25.00 0.46" euler="0 0 0.40" rgba="0.9 0.3 0.3 1" contype="1" conaffinity="1" friction="1 0.005 0.0001" />
            <geom name="terrain_box_225" type="box" size="0.5 0.75 0.46" pos="90.00 -20.00 0.46" euler="0 0 0.48" rgba="0.9 0.3 0.3 1" contype="1" conaffinity="1" friction="1 0.005 0.0001" />
            <geom name="terrain_box_226" type="box" size="0.5 0.75 0.46" pos="90.00 -15.00 0.46" euler="0 0 -0.06" rgba="0.9 0.3 0.3 1" contype="1" conaffinity="1" friction="1 0.005 0.0001" />
            <geom name="terrain_box_227" type="box" size="0.5 0.75 0.29" pos="90.00 -10.00 0.29" euler="0 0 0.41" rgba="0.2 0.8 0.4 1" contype="1" conaffinity="1" friction="1 0.005 0.0001" />
            <geom name="terrain_box_228" type="box" size="0.5 0.75 0.38" pos="90.00 -5.00 0.38" euler="0 0 0.32" rgba="0.95 0.75 0.2 1" contype="1" conaffinity="1" friction="1 0.005 0.0001" />
            <geom name="terrain_box_229" type="box" size="0.5 0.75 0.46" pos="90.00 0.00 0.46" euler="0 0 0.15" rgba="0.9 0.3 0.3 1" contype="1" conaffinity="1" friction="1 0.005 0.0001" />
            <geom name="terrain_box_230" type="box" size="0.5 0.75 0.38" pos="90.00 5.00 0.38" euler="0 0 -0.07" rgba="0.95 0.75 0.2 1" contype="1" conaffinity="1" friction="1 0.005 0.0001" />
            <geom name="terrain_box_231" type="box" size="0.5 0.75 0.38" pos="90.00 10.00 0.38" euler="0 0 -0.32" rgba="0.95 0.75 0.2 1" contype="1" conaffinity="1" friction="1 0.005 0.0001" />
            <geom name="terrain_box_232" type="box" size="0.5 0.75 0.38" pos="90.00 15.00 0.38" euler="0 0 -0.22" rgba="0.95 0.75 0.2 1" contype="1" conaffinity="1" friction="1 0.005 0.0001" />
            <geom name="terrain_box_233" type="box" size="0.5 0.75 0.19" pos="90.00 20.00 0.19" euler="0 0 -0.43" rgba="0.2 0.5 0.9 1" contype="1" conaffinity="1" friction="1 0.005 0.0001" />
            <geom name="terrain_box_234" type="box" size="0.5 0.75 0.29" pos="90.00 25.00 0.29" euler="0 0 -0.14" rgba="0.2 0.8 0.4 1" contype="1" conaffinity="1" friction="1 0.005 0.0001" />
            <geom name="terrain_box_235" type="box" size="0.5 0.75 0.29" pos="90.00 30.00 0.29" euler="0 0 0.25" rgba="0.2 0.8 0.4 1" contype="1" conaffinity="1" friction="1 0.005 0.0001" />
            <geom name="terrain_box_236" type="box" size="0.5 0.75 0.19" pos="95.00 -30.00 0.19" euler="0 0 -0.10" rgba="0.2 0.5 0.9 1" contype="1" conaffinity="1" friction="1 0.005 0.0001" />
            <geom name="terrain_box_237" type="box" size="0.5 0.75 0.38" pos="95.00 -25.00 0.38" euler="0 0 0.05" rgba="0.95 0.75 0.2 1" contype="1" conaffinity="1" friction="1 0.005 0.0001" />
            <geom name="terrain_box_238" type="box" size="0.5 0.75 0.46" pos="95.00 -20.00 0.46" euler="0 0 -0.53" rgba="0.9 0.3 0.3 1" contype="1" conaffinity="1" friction="1 0.005 0.0001" />
            <geom name="terrain_box_239" type="box" size="0.5 0.75 0.46" pos="95.00 -15.00 0.46" euler="0 0 -0.13" rgba="0.9 0.3 0.3 1" contype="1" conaffinity="1" friction="1 0.005 0.0001" />
            <geom name="terrain_box_240" type="box" size="0.5 0.75 0.19" pos="95.00 -10.00 0.19" euler="0 0 0.43" rgba="0.2 0.5 0.9 1" contype="1" conaffinity="1" friction="1 0.005 0.0001" />
            <geom name="terrain_box_241" type="box" size="0.5 0.75 0.46" pos="95.00 -5.00 0.46" euler="0 0 -0.03" rgba="0.9 0.3 0.3 1" contype="1" conaffinity="1" friction="1 0.005 0.0001" />
            <geom name="terrain_box_242" type="box" size="0.5 0.75 0.38" pos="95.00 0.00 0.38" euler="0 0 -0.24" rgba="0.95 0.75 0.2 1" contype="1" conaffinity="1" friction="1 0.005 0.0001" />
            <geom name="terrain_box_243" type="box" size="0.5 0.75 0.46" pos="95.00 5.00 0.46" euler="0 0 0.42" rgba="0.9 0.3 0.3 1" contype="1" conaffinity="1" friction="1 0.005 0.0001" />
            <geom name="terrain_box_244" type="box" size="0.5 0.75 0.46" pos="95.00 10.00 0.46" euler="0 0 0.05" rgba="0.9 0.3 0.3 1" contype="1" conaffinity="1" friction="1 0.005 0.0001" />
            <geom name="terrain_box_245" type="box" size="0.5 0.75 0.29" pos="95.00 15.00 0.29" euler="0 0 -0.01" rgba="0.2 0.8 0.4 1" contype="1" conaffinity="1" friction="1 0.005 0.0001" />
            <geom name="terrain_box_246" type="box" size="0.5 0.75 0.38" pos="95.00 20.00 0.38" euler="0 0 -0.08" rgba="0.95 0.75 0.2 1" contype="1" conaffinity="1" friction="1 0.005 0.0001" />
            <geom name="terrain_box_247" type="box" size="0.5 0.75 0.19" pos="95.00 25.00 0.19" euler="0 0 -0.13" rgba="0.2 0.5 0.9 1" contype="1" conaffinity="1" friction="1 0.005 0.0001" />
            <geom name="terrain_box_248" type="box" size="0.5 0.75 0.46" pos="95.00 30.00 0.46" euler="0 0 0.27" rgba="0.9 0.3 0.3 1" contype="1" conaffinity="1" friction="1 0.005 0.0001" />
            <geom name="terrain_box_249" type="box" size="0.5 0.75 0.46" pos="100.00 -30.00 0.46" euler="0 0 0.50" rgba="0.9 0.3 0.3 1" contype="1" conaffinity="1" friction="1 0.005 0.0001" />
            <geom name="terrain_box_250" type="box" size="0.5 0.75 0.19" pos="100.00 -25.00 0.19" euler="0 0 0.49" rgba="0.2 0.5 0.9 1" contype="1" conaffinity="1" friction="1 0.005 0.0001" />
            <geom name="terrain_box_251" type="box" size="0.5 0.75 0.19" pos="100.00 -20.00 0.19" euler="0 0 -0.50" rgba="0.2 0.5 0.9 1" contype="1" conaffinity="1" friction="1 0.005 0.0001" />
            <geom name="terrain_box_252" type="box" size="0.5 0.75 0.46" pos="100.00 -15.00 0.46" euler="0 0 -0.44" rgba="0.9 0.3 0.3 1" contype="1" conaffinity="1" friction="1 0.005 0.0001" />
            <geom name="terrain_box_253" type="box" size="0.5 0.75 0.46" pos="100.00 -10.00 0.46" euler="0 0 -0.38" rgba="0.9 0.3 0.3 1" contype="1" conaffinity="1" friction="1 0.005 0.0001" />
            <geom name="terrain_box_254" type="box" size="0.5 0.75 0.38" pos="100.00 -5.00 0.38" euler="0 0 -0.15" rgba="0.95 0.75 0.2 1" contype="1" conaffinity="1" friction="1 0.005 0.0001" />
            <geom name="terrain_box_255" type="box" size="0.5 0.75 0.29" pos="100.00 0.00 0.29" euler="0 0 -0.05" rgba="0.2 0.8 0.4 1" contype="1" conaffinity="1" friction="1 0.005 0.0001" />
            <geom name="terrain_box_256" type="box" size="0.5 0.75 0.38" pos="100.00 5.00 0.38" euler="0 0 0.31" rgba="0.95 0.75 0.2 1" contype="1" conaffinity="1" friction="1 0.005 0.0001" />
            <geom name="terrain_box_257" type="box" size="0.5 0.75 0.46" pos="100.00 10.00 0.46" euler="0 0 -0.27" rgba="0.9 0.3 0.3 1" contype="1" conaffinity="1" friction="1 0.005 0.0001" />
            <geom name="terrain_box_258" type="box" size="0.5 0.75 0.46" pos="100.00 15.00 0.46" euler="0 0 -0.30" rgba="0.9 0.3 0.3 1" contype="1" conaffinity="1" friction="1 0.005 0.0001" />
            <geom name="terrain_box_259" type="box" size="0.5 0.75 0.19" pos="100.00 20.00 0.19" euler="0 0 -0.04" rgba="0.2 0.5 0.9 1" contype="1" conaffinity="1" friction="1 0.005 0.0001" />
            <geom name="terrain_box_260" type="box" size="0.5 0.75 0.19" pos="100.00 25.00 0.19" euler="0 0 0.60" rgba="0.2 0.5 0.9 1" contype="1" conaffinity="1" friction="1 0.005 0.0001" />
            <geom name="terrain_box_261" type="box" size="0.5 0.75 0.38" pos="100.00 30.00 0.38" euler="0 0 -0.33" rgba="0.95 0.75 0.2 1" contype="1" conaffinity="1" friction="1 0.005 0.0001" />
        </body>
        <!-- <body name="finish_marker">
            <geom name="finish_post_left" type="box" size="0.08 0.08 0.82" pos="66 -0.95 0.82" rgba="1 0.85 0.2 1" contype="0" conaffinity="0"/>
            <geom name="finish_post_right" type="box" size="0.08 0.08 0.82" pos="66 0.95 0.82" rgba="1 0.85 0.2 1" contype="0" conaffinity="0"/>
            <geom name="finish_top_bar" type="box" size="0.08 1.1 0.08" pos="66 0 1.72" rgba="1 0.25 0.25 1" contype="0" conaffinity="0"/>
            <geom name="finish_panel" type="box" size="0.02 0.75 0.20" pos="66.1 0 1.35" rgba="0.1 0.1 0.1 0.9" contype="0" conaffinity="0"/>
            <site name="finish_glow" type="sphere" pos="66 0 1.35" size="0.10" rgba="1 0.95 0.3 1"/>
        </body> -->

        <light pos="0 0 1.5" dir="0 0 -1" directional="true"/>
        <geom name="floor" pos="0 0 0" size="0 0 .05" type="plane" material="grid" condim="3" contype="1" conaffinity="1"/>

    </worldbody>

    <contact>
    </contact>

    <tendon>
        <fixed limited="true" range="-1e2 0.13708" solreflimit="0.003 1" solimplimit="0.99 0.999 0.0005 0 2"  >
            <joint joint="left_ankle_roll_joint" coef="-0.2618"/>
            <joint joint="left_ankle_pitch_joint" coef="0.2618"/>
        </fixed>
        <fixed limited="true" range="-1e2 0.13708" solreflimit="0.003 1" solimplimit="0.99 0.999 0.0005 0 2"  >
            <joint joint="left_ankle_roll_joint" coef="0.2618"/>
            <joint joint="left_ankle_pitch_joint" coef="0.2618"/>
        </fixed>
        <fixed limited="true" range="-1e2 0.22846" solreflimit="0.003 1" solimplimit="0.99 0.999 0.0005 0 2"  >
            <joint joint="left_ankle_roll_joint" coef="-0.14967"/>
            <joint joint="left_ankle_pitch_joint" coef="-0.2618 "/>
        </fixed>
        <fixed limited="true" range="-1e2 0.22846" solreflimit="0.003 1" solimplimit="0.99 0.999 0.0005 0 2"  >
            <joint joint="left_ankle_roll_joint" coef="0.14967"/>
            <joint joint="left_ankle_pitch_joint" coef="-0.2618"/>
        </fixed>
        <fixed limited="true" range="-1e2 0.13708" solreflimit="0.003 1" solimplimit="0.99 0.999 0.0005 0 2"  >
            <joint joint="right_ankle_roll_joint" coef="-0.2618"/>
            <joint joint="right_ankle_pitch_joint" coef="0.2618"/>
        </fixed>
        <fixed limited="true" range="-1e2 0.13708" solreflimit="0.003 1" solimplimit="0.99 0.999 0.0005 0 2"  >
            <joint joint="right_ankle_roll_joint" coef="0.2618"/>
            <joint joint="right_ankle_pitch_joint" coef="0.2618"/>
        </fixed>
        <fixed limited="true" range="-1e2 0.22846" solreflimit="0.003 1" solimplimit="0.99 0.999 0.0005 0 2"  >
            <joint joint="right_ankle_roll_joint" coef="-0.14967"/>
            <joint joint="right_ankle_pitch_joint" coef="-0.2618 "/>
        </fixed>
        <fixed limited="true" range="-1e2 0.22846" solreflimit="0.003 1" solimplimit="0.99 0.999 0.0005 0 2"  >
            <joint joint="right_ankle_roll_joint" coef="0.14967"/>
            <joint joint="right_ankle_pitch_joint" coef="-0.2618"/>
        </fixed>
    </tendon>

    <actuator>
        <motor name="act_left_hip_pitch" joint="left_hip_pitch_joint" ctrllimited="true" ctrlrange="-88 88"/>
        <motor name="act_right_hip_pitch" joint="right_hip_pitch_joint" ctrllimited="true" ctrlrange="-88 88"/>
        <motor name="act_waist_yaw" joint="waist_yaw_joint" ctrllimited="true" ctrlrange="-88 88"/>

        <motor name="act_left_hip_roll" joint="left_hip_roll_joint" ctrllimited="true" ctrlrange="-139 139"/>
        <motor name="act_right_hip_roll" joint="right_hip_roll_joint" ctrllimited="true" ctrlrange="-139 139"/>
        <motor name="act_waist_roll" joint="waist_roll_joint" ctrllimited="true" ctrlrange="-50 50"/>

        <motor name="act_left_hip_yaw" joint="left_hip_yaw_joint" ctrllimited="true" ctrlrange="-88 88"/>
        <motor name="act_right_hip_yaw" joint="right_hip_yaw_joint" ctrllimited="true" ctrlrange="-88 88"/>
        <motor name="act_waist_pitch" joint="waist_pitch_joint" ctrllimited="true" ctrlrange="-50 50"/>

        <motor name="act_left_knee" joint="left_knee_joint" ctrllimited="true" ctrlrange="-139 139"/>
        <motor name="act_right_knee" joint="right_knee_joint" ctrllimited="true" ctrlrange="-139 139"/>

        <motor name="act_left_shoulder_pitch" joint="left_shoulder_pitch_joint" ctrllimited="true" ctrlrange="-25 25"/>
        <motor name="act_right_shoulder_pitch" joint="right_shoulder_pitch_joint" ctrllimited="true" ctrlrange="-25 25"/>

        <motor name="act_left_ankle_pitch" joint="left_ankle_pitch_joint" ctrllimited="true" ctrlrange="-50 50"/>
        <motor name="act_right_ankle_pitch" joint="right_ankle_pitch_joint" ctrllimited="true" ctrlrange="-50 50"/>

        <motor name="act_left_shoulder_roll" joint="left_shoulder_roll_joint" ctrllimited="true" ctrlrange="-25 25"/>
        <motor name="act_right_shoulder_roll" joint="right_shoulder_roll_joint" ctrllimited="true" ctrlrange="-25 25"/>

        <motor name="act_left_ankle_roll" joint="left_ankle_roll_joint" ctrllimited="true" ctrlrange="-50 50"/>
        <motor name="act_right_ankle_roll" joint="right_ankle_roll_joint" ctrllimited="true" ctrlrange="-50 50"/>

        <motor name="act_left_shoulder_yaw" joint="left_shoulder_yaw_joint" ctrllimited="true" ctrlrange="-25 25"/>
        <motor name="act_right_shoulder_yaw" joint="right_shoulder_yaw_joint" ctrllimited="true" ctrlrange="-25 25"/>

        <motor name="act_left_elbow" joint="left_elbow_joint" ctrllimited="true" ctrlrange="-25 25"/>
        <motor name="act_right_elbow" joint="right_elbow_joint" ctrllimited="true" ctrlrange="-25 25"/>

        <motor name="act_left_wrist_roll" joint="left_wrist_roll_joint" ctrllimited="true" ctrlrange="-25 25"/>
        <motor name="act_right_wrist_roll" joint="right_wrist_roll_joint" ctrllimited="true" ctrlrange="-25 25"/>

        <motor name="act_left_wrist_pitch" joint="left_wrist_pitch_joint" ctrllimited="true" ctrlrange="-5 5"/>
        <motor name="act_right_wrist_pitch" joint="right_wrist_pitch_joint" ctrllimited="true" ctrlrange="-5 5"/>
        <motor name="act_left_wrist_yaw" joint="left_wrist_yaw_joint" ctrllimited="true" ctrlrange="-5 5"/>
        <motor name="act_right_wrist_yaw" joint="right_wrist_yaw_joint" ctrllimited="true" ctrlrange="-5 5"/>
    </actuator>

    <sensor>
        <framequat name="base_quat" objtype="site" objname="imu_in_pelvis"/>
        <gyro name="base_gyro" site="imu_in_pelvis"/>
        <accelerometer name="base_accel" site="imu_in_pelvis"/>

        <framequat name="mid360_quat" objtype="site" objname="mid360"/>
        <framepos name="mid360_pos" objtype="site" objname="mid360"/>
    </sensor>

    <visual>
        <headlight diffuse="0.6 0.6 0.6" ambient="0.3 0.3 0.3" specular="0 0 0"/>
        <rgba haze="0.15 0.25 0.35 1"/>
        <global azimuth="120" elevation="-20"/>
    </visual>

    <asset>
        <texture type="skybox" builtin="gradient" rgb1="0.3 0.5 0.7" rgb2="0 0 0" width="512" height="3072"/>
        <texture name="grid" type="2d" builtin="checker" width="512" height="512" rgb1=".1 .2 .3" rgb2=".2 .3 .4"/>
        <material name="grid" texture="grid" texrepeat="1 1" texuniform="true" reflectance=".2"/>
    </asset>

</mujoco>
